Workbook

Sheet G合計
B3: 日時 | C3: 曜日 | D3: 実績 | E3: 取り分 | F3: 粗利 | G3: 実績累計 | H3: 予算 | I3: 予算累計 | K3: 差異 | L3: 1日粗利単価
B4: ='【大井町】売上'!B4 -> 46054 | C4: ='【大井町】売上'!C4 -> 日 | D4: ='【大井町】売上'!D4+'【蒲田】売上'!D4+'【巣鴨】売上'!D4 -> 0 | E4: ='【大井町】売上'!E4+'【蒲田】売上'!E4+'【巣鴨】売上'!E4 -> 0 | F4: ='【大井町】売上'!F4+'【蒲田】売上'!F4+'【巣鴨】売上'!F4 -> 0 | G4: =SUM(D4) -> 0 | H4: ='【大井町】売上'!H4+'【蒲田】売上'!H4+'【巣鴨】売上'!H4 -> 140000 | I4: =H4 -> 140000 | J4: =G4/I4 -> 0 | K4: =G4-I4 -> -140000 | L4: =M4/1 -> 0 | M4: =F4 -> 0
B5: ='【大井町】売上'!B5 -> 46055 | C5: ='【大井町】売上'!C5 -> 月 | D5: ='【大井町】売上'!D5+'【蒲田】売上'!D5+'【巣鴨】売上'!D5 -> 156000 | E5: ='【大井町】売上'!E5+'【蒲田】売上'!E5+'【巣鴨】売上'!E5 -> 85500 | F5: ='【大井町】売上'!F5+'【蒲田】売上'!F5+'【巣鴨】売上'!F5 -> 70500 | G5: =SUM(D5+G4) -> 156000 | H5: ='【大井町】売上'!H5+'【蒲田】売上'!H5+'【巣鴨】売上'!H5 -> 220000 | I5: =H5+I4 -> 360000 | J5: =G5/I5 -> 0.43333333 | K5: =G5-I5 -> -204000 | L5: =M5/1 -> 70500 | M5: =F5+M4 -> 70500
B6: ='【大井町】売上'!B6 -> 46056 | C6: ='【大井町】売上'!C6 -> 火 | D6: ='【大井町】売上'!D6+'【蒲田】売上'!D6+'【巣鴨】売上'!D6 -> 224000 | E6: ='【大井町】売上'!E6+'【蒲田】売上'!E6+'【巣鴨】売上'!E6 -> 124000 | F6: ='【大井町】売上'!F6+'【蒲田】売上'!F6+'【巣鴨】売上'!F6 -> 100000 | G6: =SUM(D6+G5) -> 380000 | H6: ='【大井町】売上'!H6+'【蒲田】売上'!H6+'【巣鴨】売上'!H6 -> 220000 | I6: =H6+I5 -> 580000 | J6: =G6/I6 -> 0.65517241 | K6: =G6-I6 -> -200000 | L6: =M6/2 -> 85250 | M6: =F6+M5 -> 170500
B7: ='【大井町】売上'!B7 -> 46057 | C7: ='【大井町】売上'!C7 -> 水 | D7: ='【大井町】売上'!D7+'【蒲田】売上'!D7+'【巣鴨】売上'!D7 -> 207000 | E7: ='【大井町】売上'!E7+'【蒲田】売上'!E7+'【巣鴨】売上'!E7 -> 117500 | F7: ='【大井町】売上'!F7+'【蒲田】売上'!F7+'【巣鴨】売上'!F7 -> 89500 | G7: =SUM(D7+G6) -> 587000 | H7: ='【大井町】売上'!H7+'【蒲田】売上'!H7+'【巣鴨】売上'!H7 -> 220000 | I7: =H7+I6 -> 800000 | J7: =G7/I7 -> 0.73375 | K7: =G7-I7 -> -213000 | L7: =M7/3 -> 86666.667 | M7: =F7+M6 -> 260000
B8: ='【大井町】売上'!B8 -> 46058 | C8: ='【大井町】売上'!C8 -> 木 | D8: ='【大井町】売上'!D8+'【蒲田】売上'!D8+'【巣鴨】売上'!D8 -> 220000 | E8: ='【大井町】売上'!E8+'【蒲田】売上'!E8+'【巣鴨】売上'!E8 -> 127925 | F8: ='【大井町】売上'!F8+'【蒲田】売上'!F8+'【巣鴨】売上'!F8 -> 92075 | G8: =SUM(D8+G7) -> 807000 | H8: ='【大井町】売上'!H8+'【蒲田】売上'!H8+'【巣鴨】売上'!H8 -> 220000 | I8: =H8+I7 -> 1020000 | J8: =G8/I8 -> 0.79117647 | K8: =G8-I8 -> -213000 | L8: =M8/4 -> 88018.75 | M8: =F8+M7 -> 352075
B9: ='【大井町】売上'!B9 -> 46059 | C9: ='【大井町】売上'!C9 -> 金 | D9: ='【大井町】売上'!D9+'【蒲田】売上'!D9+'【巣鴨】売上'!D9 -> 216000 | E9: ='【大井町】売上'!E9+'【蒲田】売上'!E9+'【巣鴨】売上'!E9 -> 119099 | F9: ='【大井町】売上'!F9+'【蒲田】売上'!F9+'【巣鴨】売上'!F9 -> 96901 | G9: =SUM(D9+G8) -> 1023000 | H9: ='【大井町】売上'!H9+'【蒲田】売上'!H9+'【巣鴨】売上'!H9 -> 220000 | I9: =H9+I8 -> 1240000 | J9: =G9/I9 -> 0.825 | K9: =G9-I9 -> -217000 | L9: =M9/5 -> 89795.2 | M9: =F9+M8 -> 448976
B10: ='【大井町】売上'!B10 -> 46060 | C10: ='【大井町】売上'!C10 -> 土 | D10: ='【大井町】売上'!D10+'【蒲田】売上'!D10+'【巣鴨】売上'!D10 -> 262000 | E10: ='【大井町】売上'!E10+'【蒲田】売上'!E10+'【巣鴨】売上'!E10 -> 139947 | F10: ='【大井町】売上'!F10+'【蒲田】売上'!F10+'【巣鴨】売上'!F10 -> 122053 | G10: =SUM(D10+G9) -> 1285000 | H10: ='【大井町】売上'!H10+'【蒲田】売上'!H10+'【巣鴨】売上'!H10 -> 220000 | I10: =H10+I9 -> 1460000 | J10: =G10/I10 -> 0.88013699 | K10: =G10-I10 -> -175000 | L10: =M10/6 -> 95171.5 | M10: =F10+M9 -> 571029
B11: ='【大井町】売上'!B11 -> 46061 | C11: ='【大井町】売上'!C11 -> 日 | D11: ='【大井町】売上'!D11+'【蒲田】売上'!D11+'【巣鴨】売上'!D11 -> 227000 | E11: ='【大井町】売上'!E11+'【蒲田】売上'!E11+'【巣鴨】売上'!E11 -> 128500 | F11: ='【大井町】売上'!F11+'【蒲田】売上'!F11+'【巣鴨】売上'!F11 -> 98500 | G11: =SUM(D11+G10) -> 1512000 | H11: ='【大井町】売上'!H11+'【蒲田】売上'!H11+'【巣鴨】売上'!H11 -> 220000 | I11: =H11+I10 -> 1680000 | J11: =G11/I11 -> 0.9 | K11: =G11-I11 -> -168000 | L11: =M11/7 -> 95647 | M11: =F11+M10 -> 669529
B12: ='【大井町】売上'!B12 -> 46062 | C12: ='【大井町】売上'!C12 -> 月 | D12: ='【大井町】売上'!D12+'【蒲田】売上'!D12+'【巣鴨】売上'!D12 -> 225000 | E12: ='【大井町】売上'!E12+'【蒲田】売上'!E12+'【巣鴨】売上'!E12 -> 126000 | F12: ='【大井町】売上'!F12+'【蒲田】売上'!F12+'【巣鴨】売上'!F12 -> 99000 | G12: =SUM(D12+G11) -> 1737000 | H12: ='【大井町】売上'!H12+'【蒲田】売上'!H12+'【巣鴨】売上'!H12 -> 220000 | I12: =H12+I11 -> 1900000 | J12: =G12/I12 -> 0.91421053 | K12: =G12-I12 -> -163000 | L12: =M12/8 -> 96066.125 | M12: =F12+M11 -> 768529
B13: ='【大井町】売上'!B13 -> 46063 | C13: ='【大井町】売上'!C13 -> 火 | D13: ='【大井町】売上'!D13+'【蒲田】売上'!D13+'【巣鴨】売上'!D13 -> 273000 | E13: ='【大井町】売上'!E13+'【蒲田】売上'!E13+'【巣鴨】売上'!E13 -> 152500 | F13: ='【大井町】売上'!F13+'【蒲田】売上'!F13+'【巣鴨】売上'!F13 -> 120500 | G13: =SUM(D13+G12) -> 2010000 | H13: ='【大井町】売上'!H13+'【蒲田】売上'!H13+'【巣鴨】売上'!H13 -> 220000 | I13: =H13+I12 -> 2120000 | J13: =G13/I13 -> 0.94811321 | K13: =G13-I13 -> -110000 | L13: =M13/9 -> 98781 | M13: =F13+M12 -> 889029
B14: ='【大井町】売上'!B14 -> 46064 | C14: ='【大井町】売上'!C14 -> 水 | D14: ='【大井町】売上'!D14+'【蒲田】売上'!D14+'【巣鴨】売上'!D14 -> 171000 | E14: ='【大井町】売上'!E14+'【蒲田】売上'!E14+'【巣鴨】売上'!E14 -> 95000 | F14: ='【大井町】売上'!F14+'【蒲田】売上'!F14+'【巣鴨】売上'!F14 -> 76000 | G14: =SUM(D14+G13) -> 2181000 | H14: ='【大井町】売上'!H14+'【蒲田】売上'!H14+'【巣鴨】売上'!H14 -> 220000 | I14: =H14+I13 -> 2340000 | J14: =G14/I14 -> 0.93205128 | K14: =G14-I14 -> -159000 | L14: =M14/10 -> 96502.9 | M14: =F14+M13 -> 965029
B15: ='【大井町】売上'!B15 -> 46065 | C15: ='【大井町】売上'!C15 -> 木 | D15: ='【大井町】売上'!D15+'【蒲田】売上'!D15+'【巣鴨】売上'!D15 -> 225000 | E15: ='【大井町】売上'!E15+'【蒲田】売上'!E15+'【巣鴨】売上'!E15 -> 130347 | F15: ='【大井町】売上'!F15+'【蒲田】売上'!F15+'【巣鴨】売上'!F15 -> 94653 | G15: =SUM(D15+G14) -> 2406000 | H15: ='【大井町】売上'!H15+'【蒲田】売上'!H15+'【巣鴨】売上'!H15 -> 220000 | I15: =H15+I14 -> 2560000 | J15: =G15/I15 -> 0.93984375 | K15: =G15-I15 -> -154000 | L15: =M15/11 -> 96334.727 | M15: =F15+M14 -> 1059682
B16: ='【大井町】売上'!B16 -> 46066 | C16: ='【大井町】売上'!C16 -> 金 | D16: ='【大井町】売上'!D16+'【蒲田】売上'!D16+'【巣鴨】売上'!D16 -> 133000 | E16: ='【大井町】売上'!E16+'【蒲田】売上'!E16+'【巣鴨】売上'!E16 -> 73000 | F16: ='【大井町】売上'!F16+'【蒲田】売上'!F16+'【巣鴨】売上'!F16 -> 60000 | G16: =SUM(D16+G15) -> 2539000 | H16: ='【大井町】売上'!H16+'【蒲田】売上'!H16+'【巣鴨】売上'!H16 -> 220000 | I16: =H16+I15 -> 2780000 | J16: =G16/I16 -> 0.91330935 | K16: =G16-I16 -> -241000 | L16: =M16/12 -> 93306.833 | M16: =F16+M15 -> 1119682
B17: ='【大井町】売上'!B17 -> 46067 | C17: ='【大井町】売上'!C17 -> 土 | D17: ='【大井町】売上'!D17+'【蒲田】売上'!D17+'【巣鴨】売上'!D17 -> 152000 | E17: ='【大井町】売上'!E17+'【蒲田】売上'!E17+'【巣鴨】売上'!E17 -> 88822 | F17: ='【大井町】売上'!F17+'【蒲田】売上'!F17+'【巣鴨】売上'!F17 -> 63178 | G17: =SUM(D17+G16) -> 2691000 | H17: ='【大井町】売上'!H17+'【蒲田】売上'!H17+'【巣鴨】売上'!H17 -> 220000 | I17: =H17+I16 -> 3000000 | J17: =G17/I17 -> 0.897 | K17: =G17-I17 -> -309000 | L17: =M17/13 -> 90989.231 | M17: =F17+M16 -> 1182860
B18: ='【大井町】売上'!B18 -> 46068 | C18: ='【大井町】売上'!C18 -> 日 | D18: ='【大井町】売上'!D18+'【蒲田】売上'!D18+'【巣鴨】売上'!D18 -> 227000 | E18: ='【大井町】売上'!E18+'【蒲田】売上'!E18+'【巣鴨】売上'!E18 -> 123770 | F18: ='【大井町】売上'!F18+'【蒲田】売上'!F18+'【巣鴨】売上'!F18 -> 103230 | G18: =SUM(D18+G17) -> 2918000 | H18: ='【大井町】売上'!H18+'【蒲田】売上'!H18+'【巣鴨】売上'!H18 -> 220000 | I18: =H18+I17 -> 3220000 | J18: =G18/I18 -> 0.90621118 | K18: =G18-I18 -> -302000 | L18: =M18/14 -> 91863.571 | M18: =F18+M17 -> 1286090
B19: ='【大井町】売上'!B19 -> 46069 | C19: ='【大井町】売上'!C19 -> 月 | D19: ='【大井町】売上'!D19+'【蒲田】売上'!D19+'【巣鴨】売上'!D19 -> 212000 | E19: ='【大井町】売上'!E19+'【蒲田】売上'!E19+'【巣鴨】売上'!E19 -> 121000 | F19: ='【大井町】売上'!F19+'【蒲田】売上'!F19+'【巣鴨】売上'!F19 -> 91000 | G19: =SUM(D19+G18) -> 3130000 | H19: ='【大井町】売上'!H19+'【蒲田】売上'!H19+'【巣鴨】売上'!H19 -> 220000 | I19: =H19+I18 -> 3440000 | J19: =G19/I19 -> 0.90988372 | K19: =G19-I19 -> -310000 | L19: =M19/15 -> 91806 | M19: =F19+M18 -> 1377090
B20: ='【大井町】売上'!B20 -> 46070 | C20: ='【大井町】売上'!C20 -> 火 | D20: ='【大井町】売上'!D20+'【蒲田】売上'!D20+'【巣鴨】売上'!D20 -> 182000 | E20: ='【大井町】売上'!E20+'【蒲田】売上'!E20+'【巣鴨】売上'!E20 -> 106596 | F20: ='【大井町】売上'!F20+'【蒲田】売上'!F20+'【巣鴨】売上'!F20 -> 75404 | G20: =SUM(D20+G19) -> 3312000 | H20: ='【大井町】売上'!H20+'【蒲田】売上'!H20+'【巣鴨】売上'!H20 -> 220000 | I20: =H20+I19 -> 3660000 | J20: =G20/I20 -> 0.90491803 | K20: =G20-I20 -> -348000 | L20: =M20/16 -> 90780.875 | M20: =F20+M19 -> 1452494
B21: ='【大井町】売上'!B21 -> 46071 | C21: ='【大井町】売上'!C21 -> 水 | D21: ='【大井町】売上'!D21+'【蒲田】売上'!D21+'【巣鴨】売上'!D21 -> 179000 | E21: ='【大井町】売上'!E21+'【蒲田】売上'!E21+'【巣鴨】売上'!E21 -> 101500 | F21: ='【大井町】売上'!F21+'【蒲田】売上'!F21+'【巣鴨】売上'!F21 -> 77500 | G21: =SUM(D21+G20) -> 3491000 | H21: ='【大井町】売上'!H21+'【蒲田】売上'!H21+'【巣鴨】売上'!H21 -> 220000 | I21: =H21+I20 -> 3880000 | J21: =G21/I21 -> 0.89974227 | K21: =G21-I21 -> -389000 | L21: =M21/17 -> 89999.647 | M21: =F21+M20 -> 1529994
B22: ='【大井町】売上'!B22 -> 46072 | C22: ='【大井町】売上'!C22 -> 木 | D22: ='【大井町】売上'!D22+'【蒲田】売上'!D22+'【巣鴨】売上'!D22 -> 170000 | E22: ='【大井町】売上'!E22+'【蒲田】売上'!E22+'【巣鴨】売上'!E22 -> 99264 | F22: ='【大井町】売上'!F22+'【蒲田】売上'!F22+'【巣鴨】売上'!F22 -> 70736 | G22: =SUM(D22+G21) -> 3661000 | H22: ='【大井町】売上'!H22+'【蒲田】売上'!H22+'【巣鴨】売上'!H22 -> 220000 | I22: =H22+I21 -> 4100000 | J22: =G22/I22 -> 0.89292683 | K22: =G22-I22 -> -439000 | L22: =M22/18 -> 88929.444 | M22: =F22+M21 -> 1600730
B23: ='【大井町】売上'!B23 -> 46073 | C23: ='【大井町】売上'!C23 -> 金 | D23: ='【大井町】売上'!D23+'【蒲田】売上'!D23+'【巣鴨】売上'!D23 -> 197000 | E23: ='【大井町】売上'!E23+'【蒲田】売上'!E23+'【巣鴨】売上'!E23 -> 112019 | F23: ='【大井町】売上'!F23+'【蒲田】売上'!F23+'【巣鴨】売上'!F23 -> 84981 | G23: =SUM(D23+G22) -> 3858000 | H23: ='【大井町】売上'!H23+'【蒲田】売上'!H23+'【巣鴨】売上'!H23 -> 220000 | I23: =H23+I22 -> 4320000 | J23: =G23/I23 -> 0.89305556 | K23: =G23-I23 -> -462000 | L23: =M23/19 -> 88721.632 | M23: =F23+M22 -> 1685711
B24: ='【大井町】売上'!B24 -> 46074 | C24: ='【大井町】売上'!C24 -> 土 | D24: ='【大井町】売上'!D24+'【蒲田】売上'!D24+'【巣鴨】売上'!D24 -> 142000 | E24: ='【大井町】売上'!E24+'【蒲田】売上'!E24+'【巣鴨】売上'!E24 -> 81827 | F24: ='【大井町】売上'!F24+'【蒲田】売上'!F24+'【巣鴨】売上'!F24 -> 60173 | G24: =SUM(D24+G23) -> 4000000 | H24: ='【大井町】売上'!H24+'【蒲田】売上'!H24+'【巣鴨】売上'!H24 -> 220000 | I24: =H24+I23 -> 4540000 | J24: =G24/I24 -> 0.88105727 | K24: =G24-I24 -> -540000 | L24: =M24/20 -> 87294.2 | M24: =F24+M23 -> 1745884
B25: ='【大井町】売上'!B25 -> 46075 | C25: ='【大井町】売上'!C25 -> 日 | D25: ='【大井町】売上'!D25+'【蒲田】売上'!D25+'【巣鴨】売上'!D25 -> 123000 | E25: ='【大井町】売上'!E25+'【蒲田】売上'!E25+'【巣鴨】売上'!E25 -> 65500 | F25: ='【大井町】売上'!F25+'【蒲田】売上'!F25+'【巣鴨】売上'!F25 -> 57500 | G25: =SUM(D25+G24) -> 4123000 | H25: ='【大井町】売上'!H25+'【蒲田】売上'!H25+'【巣鴨】売上'!H25 -> 220000 | I25: =H25+I24 -> 4760000 | J25: =G25/I25 -> 0.86617647 | K25: =G25-I25 -> -637000 | L25: =M25/21 -> 85875.429 | M25: =F25+M24 -> 1803384
B26: ='【大井町】売上'!B26 -> 46076 | C26: ='【大井町】売上'!C26 -> 月 | D26: ='【大井町】売上'!D26+'【蒲田】売上'!D26+'【巣鴨】売上'!D26 -> 0 | E26: ='【大井町】売上'!E26+'【蒲田】売上'!E26+'【巣鴨】売上'!E26 -> 0 | F26: ='【大井町】売上'!F26+'【蒲田】売上'!F26+'【巣鴨】売上'!F26 -> 0 | G26: =SUM(D26+G25) -> 4123000 | H26: ='【大井町】売上'!H26+'【蒲田】売上'!H26+'【巣鴨】売上'!H26 -> 220000 | I26: =H26+I25 -> 4980000 | J26: =G26/I26 -> 0.82791165 | K26: =G26-I26 -> -857000 | L26: =M26/22 -> 81972 | M26: =F26+M25 -> 1803384
B27: ='【大井町】売上'!B27 -> 46077 | C27: ='【大井町】売上'!C27 -> 火 | D27: ='【大井町】売上'!D27+'【蒲田】売上'!D27+'【巣鴨】売上'!D27 -> 0 | E27: ='【大井町】売上'!E27+'【蒲田】売上'!E27+'【巣鴨】売上'!E27 -> 0 | F27: ='【大井町】売上'!F27+'【蒲田】売上'!F27+'【巣鴨】売上'!F27 -> 0 | G27: =SUM(D27+G26) -> 4123000 | H27: ='【大井町】売上'!H27+'【蒲田】売上'!H27+'【巣鴨】売上'!H27 -> 220000 | I27: =H27+I26 -> 5200000 | J27: =G27/I27 -> 0.79288462 | K27: =G27-I27 -> -1077000 | L27: =M27/23 -> 78408 | M27: =F27+M26 -> 1803384
B28: ='【大井町】売上'!B28 -> 46078 | C28: ='【大井町】売上'!C28 -> 水 | D28: ='【大井町】売上'!D28+'【蒲田】売上'!D28+'【巣鴨】売上'!D28 -> 0 | E28: ='【大井町】売上'!E28+'【蒲田】売上'!E28+'【巣鴨】売上'!E28 -> 0 | F28: ='【大井町】売上'!F28+'【蒲田】売上'!F28+'【巣鴨】売上'!F28 -> 0 | G28: =SUM(D28+G27) -> 4123000 | H28: ='【大井町】売上'!H28+'【蒲田】売上'!H28+'【巣鴨】売上'!H28 -> 220000 | I28: =H28+I27 -> 5420000 | J28: =G28/I28 -> 0.76070111 | K28: =G28-I28 -> -1297000 | L28: =M28/24 -> 75141 | M28: =F28+M27 -> 1803384
B29: ='【大井町】売上'!B29 -> 46079 | C29: ='【大井町】売上'!C29 -> 木 | D29: ='【大井町】売上'!D29+'【蒲田】売上'!D29+'【巣鴨】売上'!D29 -> 0 | E29: ='【大井町】売上'!E29+'【蒲田】売上'!E29+'【巣鴨】売上'!E29 -> 0 | F29: ='【大井町】売上'!F29+'【蒲田】売上'!F29+'【巣鴨】売上'!F29 -> 0 | G29: =SUM(D29+G28) -> 4123000 | H29: ='【大井町】売上'!H29+'【蒲田】売上'!H29+'【巣鴨】売上'!H29 -> 220000 | I29: =H29+I28 -> 5640000 | J29: =G29/I29 -> 0.73102837 | K29: =G29-I29 -> -1517000 | L29: =M29/25 -> 72135.36 | M29: =F29+M28 -> 1803384
B30: ='【大井町】売上'!B30 -> 46080 | C30: ='【大井町】売上'!C30 -> 金 | D30: ='【大井町】売上'!D30+'【蒲田】売上'!D30+'【巣鴨】売上'!D30 -> 0 | E30: ='【大井町】売上'!E30+'【蒲田】売上'!E30+'【巣鴨】売上'!E30 -> 0 | F30: ='【大井町】売上'!F30+'【蒲田】売上'!F30+'【巣鴨】売上'!F30 -> 0 | G30: =SUM(D30+G29) -> 4123000 | H30: ='【大井町】売上'!H30+'【蒲田】売上'!H30+'【巣鴨】売上'!H30 -> 220000 | I30: =H30+I29 -> 5860000 | J30: =G30/I30 -> 0.70358362 | K30: =G30-I30 -> -1737000 | L30: =M30/26 -> 69360.923 | M30: =F30+M29 -> 1803384
B31: ='【大井町】売上'!B31 -> 46081 | C31: ='【大井町】売上'!C31 -> 土 | D31: ='【大井町】売上'!D31+'【蒲田】売上'!D31+'【巣鴨】売上'!D31 -> 0 | E31: ='【大井町】売上'!E31+'【蒲田】売上'!E31+'【巣鴨】売上'!E31 -> 0 | F31: ='【大井町】売上'!F31+'【蒲田】売上'!F31+'【巣鴨】売上'!F31 -> 0 | G31: =SUM(D31+G30) -> 4123000 | H31: ='【大井町】売上'!H31+'【蒲田】売上'!H31+'【巣鴨】売上'!H31 -> 220000 | I31: =H31+I30 -> 6080000 | J31: =G31/I31 -> 0.678125 | K31: =G31-I31 -> -1957000 | L31: =M31/27 -> 66792 | M31: =F31+M30 -> 1803384
B32: ='【大井町】売上'!B32 | C32: ='【大井町】売上'!C32 | D32: ='【大井町】売上'!D32+'【蒲田】売上'!D32+'【巣鴨】売上'!D32 -> 0 | E32: ='【大井町】売上'!E32+'【蒲田】売上'!E32+'【巣鴨】売上'!E32 -> 0 | F32: ='【大井町】売上'!F32+'【蒲田】売上'!F32+'【巣鴨】売上'!F32 -> 0 | G32: =SUM(D32+G31) -> 4123000 | H32: ='【大井町】売上'!H32+'【蒲田】売上'!H32+'【巣鴨】売上'!H32 -> 220000 | I32: =H32+I31 -> 6300000 | J32: =G32/I32 -> 0.65444444 | K32: =G32-I32 -> -2177000 | L32: =M32/28 -> 64406.571 | M32: =F32+M31 -> 1803384
B33: ='【大井町】売上'!B33 | C33: ='【大井町】売上'!C33 | D33: ='【大井町】売上'!D33+'【蒲田】売上'!D33+'【巣鴨】売上'!D33 -> 0 | E33: ='【大井町】売上'!E33+'【蒲田】売上'!E33+'【巣鴨】売上'!E33 -> 0 | F33: ='【大井町】売上'!F33+'【蒲田】売上'!F33+'【巣鴨】売上'!F33 -> 0 | G33: =SUM(D33+G32) -> 4123000 | H33: ='【大井町】売上'!H33+'【蒲田】売上'!H33+'【巣鴨】売上'!H33 -> 220000 | I33: =H33+I32 -> 6520000 | J33: =G33/I33 -> 0.63236196 | K33: =G33-I33 -> -2397000 | L33: =M33/29 -> 62185.655 | M33: =F33+M32 -> 1803384
B34: ='【大井町】売上'!B34 | C34: ='【大井町】売上'!C34 | D34: ='【大井町】売上'!D34+'【蒲田】売上'!D34+'【巣鴨】売上'!D34 -> 0 | E34: ='【大井町】売上'!E34+'【蒲田】売上'!E34+'【巣鴨】売上'!E34 -> 0 | F34: ='【大井町】売上'!F34+'【蒲田】売上'!F34+'【巣鴨】売上'!F34 -> 0 | G34: =G33+D34 -> 4123000 | H34: ='【大井町】売上'!H34+'【蒲田】売上'!H34+'【巣鴨】売上'!H34 -> 220000 | I34: =H34+I33 -> 6740000 | J34: =G34/I34 -> 0.61172107 | K34: =G34-I34 -> -2617000 | L34: =M34/30 -> 60112.8 | M34: =F34+M33 -> 1803384
B35: 月合計 | D35: =SUM(D4:D34) -> 4123000 | E35: =SUM(E4:E34) -> 2319616 | F35: =SUM(D35-E35) -> 1803384 | G35: =SUM(G34) -> 4123000 | H35: =SUM(H4:H34) -> 6740000 | I35: =H35 -> 6740000

Sheet 【大井町】売上
B1: 46054
B3: 日時 | C3: 曜日 | D3: 実績 | E3: 取り分 | F3: 粗利 | G3: 実績累計 | H3: 予算 | I3: 予算累計 | J3: 進捗 | K3: 差異 | L3: 客単価 | M3: 新規 | N3: 顧客 | O3: 指名
B4: 46054 | C4: 日 | D4: ='シフト'!J7 -> 0 | E4: ='シフト'!K7 -> 0 | F4: =D4-E4 -> 0 | G4: =SUM(D4) -> 0 | I4: =SUM(H4) -> 0 | J4: =G4/I4 -> #DIV/0! | K4: =G4-I4 -> 0 | L4: =D4/SUM(M4:O4) -> #DIV/0! | M4: ='シフト'!N6 -> 0 | N4: ='シフト'!O6 -> 0 | O4: ='シフト'!P6 -> 0
B5: 46055 | C5: 月 | D5: ='シフト'!J12 -> 74000 | E5: ='シフト'!K12 -> 41000 | F5: =D5-E5 -> 33000 | G5: =SUM(D5+G4) -> 74000 | H5: 80000 | I5: =SUM(H5+I4) -> 80000 | J5: =G5/I5 -> 0.925 | K5: =G5-I5 -> -6000 | L5: =D5/SUM(M5:O5) -> 18500 | M5: ='シフト'!N11 -> 0 | N5: ='シフト'!O11 -> 4 | O5: ='シフト'!P11 -> 0
B6: 46056 | C6: 火 | D6: ='シフト'!J17 -> 90000 | E6: ='シフト'!K17 -> 47500 | F6: =D6-E6 -> 42500 | G6: =SUM(D6+G5) -> 164000 | H6: 80000 | I6: =SUM(H6+I5) -> 160000 | J6: =G6/I6 -> 1.025 | K6: =G6-I6 -> 4000 | L6: =D6/SUM(M6:O6) -> 22500 | M6: ='シフト'!N16 -> 0 | N6: ='シフト'!O16 -> 4 | O6: ='シフト'!P16 -> 0
B7: 46057 | C7: 水 | D7: ='シフト'!J22 -> 118000 | E7: ='シフト'!K22 -> 66500 | F7: =D7-E7 -> 51500 | G7: =SUM(D7+G6) -> 282000 | H7: 80000 | I7: =SUM(H7+I6) -> 240000 | J7: =G7/I7 -> 1.175 | K7: =G7-I7 -> 42000 | L7: =D7/SUM(M7:O7) -> 16857.143 | M7: ='シフト'!N21 -> 2 | N7: ='シフト'!O21 -> 3 | O7: ='シフト'!P21 -> 2
B8: 46058 | C8: 木 | D8: ='シフト'!J27 -> 131000 | E8: ='シフト'!K27 -> 77000 | F8: =D8-E8 -> 54000 | G8: =SUM(D8+G7) -> 413000 | H8: 80000 | I8: =SUM(H8+I7) -> 320000 | J8: =G8/I8 -> 1.290625 | K8: =G8-I8 -> 93000 | L8: =D8/SUM(M8:O8) -> 18714.286 | M8: ='シフト'!N26 -> 1 | N8: ='シフト'!O26 -> 3 | O8: ='シフト'!P26 -> 3
B9: 46059 | C9: 金 | D9: ='シフト'!J32 -> 57000 | E9: ='シフト'!K32 -> 33000 | F9: =D9-E9 -> 24000 | G9: =SUM(D9+G8) -> 470000 | H9: 80000 | I9: =SUM(H9+I8) -> 400000 | J9: =G9/I9 -> 1.175 | K9: =G9-I9 -> 70000 | L9: =D9/SUM(M9:O9) -> 14250 | M9: ='シフト'!N31 -> 1 | N9: ='シフト'!O31 -> 2 | O9: ='シフト'!P31 -> 1
B10: 46060 | C10: 土 | D10: ='シフト'!J37 -> 166000 | E10: ='シフト'!K37 -> 85000 | F10: =D10-E10 -> 81000 | G10: =SUM(D10+G9) -> 636000 | H10: 80000 | I10: =SUM(H10+I9) -> 480000 | J10: =G10/I10 -> 1.325 | K10: =G10-I10 -> 156000 | L10: =D10/SUM(M10:O10) -> 16600 | M10: ='シフト'!N36 -> 3 | N10: ='シフト'!O36 -> 7 | O10: ='シフト'!P36 -> 0
A11: =SUM(D4:D10) -> 636000 | B11: 46061 | C11: 日 | D11: ='シフト'!J42 -> 148000 | E11: ='シフト'!K42 -> 83500 | F11: =D11-E11 -> 64500 | G11: =SUM(D11+G10) -> 784000 | H11: 80000 | I11: =SUM(H11+I10) -> 560000 | J11: =G11/I11 -> 1.4 | K11: =G11-I11 -> 224000 | L11: =D11/SUM(M11:O11) -> 16444.444 | M11: ='シフト'!N41 -> 0 | N11: ='シフト'!O41 -> 4 | O11: ='シフト'!P41 -> 5
B12: 46062 | C12: 月 | D12: ='シフト'!J47 -> 55000 | E12: ='シフト'!K47 -> 31500 | F12: =D12-E12 -> 23500 | G12: =SUM(D12+G11) -> 839000 | H12: 80000 | I12: =SUM(H12+I11) -> 640000 | J12: =G12/I12 -> 1.3109375 | K12: =G12-I12 -> 199000 | L12: =D12/SUM(M12:O12) -> 18333.333 | M12: ='シフト'!N46 -> 0 | N12: ='シフト'!O46 -> 2 | O12: ='シフト'!P46 -> 1
B13: 46063 | C13: 火 | D13: ='シフト'!J52 -> 101000 | E13: ='シフト'!K52 -> 56500 | F13: =D13-E13 -> 44500 | G13: =SUM(D13+G12) -> 940000 | H13: 80000 | I13: =SUM(H13+I12) -> 720000 | J13: =G13/I13 -> 1.3055556 | K13: =G13-I13 -> 220000 | L13: =D13/SUM(M13:O13) -> 16833.333 | M13: ='シフト'!N51 -> 0 | N13: ='シフト'!O51 -> 4 | O13: ='シフト'!P51 -> 2
B14: 46064 | C14: 水 | D14: ='シフト'!J57 -> 63000 | E14: ='シフト'!K57 -> 35500 | F14: =D14-E14 -> 27500 | G14: =SUM(D14+G13) -> 1003000 | H14: 80000 | I14: =SUM(H14+I13) -> 800000 | J14: =G14/I14 -> 1.25375 | K14: =G14-I14 -> 203000 | L14: =D14/SUM(M14:O14) -> 15750 | M14: ='シフト'!N56 -> 0 | N14: ='シフト'!O56 -> 4 | O14: ='シフト'!P56 -> 0
B15: 46065 | C15: 木 | D15: ='シフト'!J62 -> 103000 | E15: ='シフト'!K62 -> 58500 | F15: =D15-E15 -> 44500 | G15: =SUM(D15+G14) -> 1106000 | H15: 80000 | I15: =SUM(H15+I14) -> 880000 | J15: =G15/I15 -> 1.2568182 | K15: =G15-I15 -> 226000 | L15: =D15/SUM(M15:O15) -> 17166.667 | M15: ='シフト'!N61 -> 1 | N15: ='シフト'!O61 -> 4 | O15: ='シフト'!P61 -> 1
B16: 46066 | C16: 金 | D16: ='シフト'!J67 -> 52000 | E16: ='シフト'!K67 -> 27000 | F16: =D16-E16 -> 25000 | G16: =SUM(D16+G15) -> 1158000 | H16: 80000 | I16: =SUM(H16+I15) -> 960000 | J16: =G16/I16 -> 1.20625 | K16: =G16-I16 -> 198000 | L16: =D16/SUM(M16:O16) -> 13000 | M16: ='シフト'!N66 -> 1 | N16: ='シフト'!O66 -> 0 | O16: ='シフト'!P66 -> 3
B17: 46067 | C17: 土 | D17: ='シフト'!J72 -> 76000 | E17: ='シフト'!K72 -> 41000 | F17: =D17-E17 -> 35000 | G17: =SUM(D17+G16) -> 1234000 | H17: 80000 | I17: =SUM(H17+I16) -> 1040000 | J17: =G17/I17 -> 1.1865385 | K17: =G17-I17 -> 194000 | L17: =D17/SUM(M17:O17) -> 15200 | M17: ='シフト'!N71 -> 0 | N17: ='シフト'!O71 -> 5 | O17: ='シフト'!P71 -> 0
A18: =SUM(D11:D17) -> 598000 | B18: 46068 | C18: 日 | D18: ='シフト'!J77 -> 76000 | E18: ='シフト'!K77 -> 46270 | F18: =D18-E18 -> 29730 | G18: =SUM(D18+G17) -> 1310000 | H18: 80000 | I18: =SUM(H18+I17) -> 1120000 | J18: =G18/I18 -> 1.1696429 | K18: =G18-I18 -> 190000 | L18: =D18/SUM(M18:O18) -> 15200 | M18: ='シフト'!N76 -> 1 | N18: ='シフト'!O76 -> 3 | O18: ='シフト'!P76 -> 1
B19: 46069 | C19: 月 | D19: ='シフト'!J82 -> 47000 | E19: ='シフト'!K82 -> 26500 | F19: =D19-E19 -> 20500 | G19: =SUM(D19+G18) -> 1357000 | H19: 80000 | I19: =SUM(H19+I18) -> 1200000 | J19: =G19/I19 -> 1.1308333 | K19: =G19-I19 -> 157000 | L19: =D19/SUM(M19:O19) -> 15666.667 | M19: ='シフト'!N81 -> 0 | N19: ='シフト'!O81 -> 2 | O19: ='シフト'!P81 -> 1
B20: 46070 | C20: 火 | D20: ='シフト'!J87 -> 64000 | E20: ='シフト'!K87 -> 35996 | F20: =D20-E20 -> 28004 | G20: =SUM(D20+G19) -> 1421000 | H20: 80000 | I20: =SUM(H20+I19) -> 1280000 | J20: =G20/I20 -> 1.1101562 | K20: =G20-I20 -> 141000 | L20: =D20/SUM(M20:O20) -> 16000 | M20: ='シフト'!N86 -> 1 | N20: ='シフト'!O86 -> 3 | O20: ='シフト'!P86 -> 0
B21: 46071 | C21: 水 | D21: ='シフト'!J92 -> 57000 | E21: ='シフト'!K92 -> 30500 | F21: =D21-E21 -> 26500 | G21: =SUM(D21+G20) -> 1478000 | H21: 80000 | I21: =SUM(H21+I20) -> 1360000 | J21: =G21/I21 -> 1.0867647 | K21: =G21-I21 -> 118000 | L21: =D21/SUM(M21:O21) -> 14250 | M21: ='シフト'!N91 -> 0 | N21: ='シフト'!O91 -> 3 | O21: ='シフト'!P91 -> 1
B22: 46072 | C22: 木 | D22: ='シフト'!J97 -> 44000 | E22: ='シフト'!K97 -> 25000 | F22: =D22-E22 -> 19000 | G22: =SUM(D22+G21) -> 1522000 | H22: 80000 | I22: =SUM(H22+I21) -> 1440000 | J22: =G22/I22 -> 1.0569444 | K22: =G22-I22 -> 82000 | L22: =D22/SUM(M22:O22) -> 14666.667 | M22: ='シフト'!N96 -> 0 | N22: ='シフト'!O96 -> 2 | O22: ='シフト'!P96 -> 1
B23: 46073 | C23: 金 | D23: ='シフト'!J102 -> 92000 | E23: ='シフト'!K102 -> 51000 | F23: =D23-E23 -> 41000 | G23: =SUM(D23+G22) -> 1614000 | H23: 80000 | I23: =SUM(H23+I22) -> 1520000 | J23: =G23/I23 -> 1.0618421 | K23: =G23-I23 -> 94000 | L23: =D23/SUM(M23:O23) -> 15333.333 | M23: ='シフト'!N101 -> 1 | N23: ='シフト'!O101 -> 2 | O23: ='シフト'!P101 -> 3
B24: 46074 | C24: 土 | D24: ='シフト'!J107 -> 96000 | E24: ='シフト'!K107 -> 55827 | F24: =D24-E24 -> 40173 | G24: =SUM(D24+G23) -> 1710000 | H24: 80000 | I24: =SUM(H24+I23) -> 1600000 | J24: =G24/I24 -> 1.06875 | K24: =G24-I24 -> 110000 | L24: =D24/SUM(M24:O24) -> 16000 | M24: ='シフト'!N106 -> 0 | N24: ='シフト'!O106 -> 4 | O24: ='シフト'!P106 -> 2
A25: =SUM(D18:D24) -> 476000 | B25: 46075 | C25: 日 | D25: ='シフト'!J112 -> 57000 | E25: ='シフト'!K112 -> 30500 | F25: =D25-E25 -> 26500 | G25: =SUM(D25+G24) -> 1767000 | H25: 80000 | I25: =SUM(H25+I24) -> 1680000 | J25: =G25/I25 -> 1.0517857 | K25: =G25-I25 -> 87000 | L25: =D25/SUM(M25:O25) -> 3.9299504 | M25: ='シフト'!N111 -> 1 | N25: ='シフト'!O111 -> 3 | O25: ='シフト'!P111 -> 14500
B26: 46076 | C26: 月 | D26: ='シフト'!J117 -> 0 | E26: ='シフト'!K117 -> 0 | F26: =D26-E26 -> 0 | G26: =SUM(D26+G25) -> 1767000 | H26: 80000 | I26: =SUM(H26+I25) -> 1760000 | J26: =G26/I26 -> 1.0039773 | K26: =G26-I26 -> 7000 | L26: =D26/SUM(M26:O26) -> #DIV/0! | M26: ='シフト'!N116 -> 0 | N26: ='シフト'!O116 -> 0 | O26: ='シフト'!P116 -> 0
B27: 46077 | C27: 火 | D27: ='シフト'!J122 -> 0 | E27: ='シフト'!K122 -> 0 | F27: =D27-E27 -> 0 | G27: =SUM(D27+G26) -> 1767000 | H27: 80000 | I27: =SUM(H27+I26) -> 1840000 | J27: =G27/I27 -> 0.96032609 | K27: =G27-I27 -> -73000 | L27: =D27/SUM(M27:O27) -> #DIV/0! | M27: ='シフト'!N121 -> 0 | N27: ='シフト'!O121 -> 0 | O27: ='シフト'!P121 -> 0
B28: 46078 | C28: 水 | D28: ='シフト'!J127 -> 0 | E28: ='シフト'!K127 -> 0 | F28: =D28-E28 -> 0 | G28: =SUM(D28+G27) -> 1767000 | H28: 80000 | I28: =SUM(H28+I27) -> 1920000 | J28: =G28/I28 -> 0.9203125 | K28: =G28-I28 -> -153000 | L28: =D28/SUM(M28:O28) -> 0 | M28: ='シフト'!N126 -> 0 | N28: ='シフト'!O126 -> 0 | O28: ='シフト'!P126 -> 1
B29: 46079 | C29: 木 | D29: ='シフト'!J132 -> 0 | E29: ='シフト'!K132 -> 0 | F29: =D29-E29 -> 0 | G29: =SUM(D29+G28) -> 1767000 | H29: 80000 | I29: =SUM(H29+I28) -> 2000000 | J29: =G29/I29 -> 0.8835 | K29: =G29-I29 -> -233000 | L29: =D29/SUM(M29:O29) -> 0 | M29: ='シフト'!N131 -> 0 | N29: ='シフト'!O131 -> 0 | O29: ='シフト'!P131 -> 2
B30: 46080 | C30: 金 | D30: ='シフト'!J137 -> 0 | E30: ='シフト'!K137 -> 0 | F30: =D30-E30 -> 0 | G30: =SUM(D30+G29) -> 1767000 | H30: 80000 | I30: =SUM(H30+I29) -> 2080000 | J30: =G30/I30 -> 0.84951923 | K30: =G30-I30 -> -313000 | L30: =D30/SUM(M30:O30) -> 0 | M30: ='シフト'!N136 -> 0 | N30: ='シフト'!O136 -> 0 | O30: ='シフト'!P136 -> 1
B31: 46081 | C31: 土 | D31: ='シフト'!J142 -> 0 | E31: ='シフト'!K142 -> 0 | F31: =D31-E31 -> 0 | G31: =SUM(D31+G30) -> 1767000 | H31: 80000 | I31: =SUM(H31+I30) -> 2160000 | J31: =G31/I31 -> 0.81805556 | K31: =G31-I31 -> -393000 | L31: =D31/SUM(M31:O31) -> #DIV/0! | M31: ='シフト'!N141 -> 0 | N31: ='シフト'!O141 -> 0 | O31: ='シフト'!P141 -> 0
A32: =SUM(D25:D31) -> 57000 | D32: ='シフト'!J147 -> 0 | E32: ='シフト'!K147 -> 0 | F32: =D32-E32 -> 0 | G32: =SUM(D32+G31) -> 1767000 | H32: 80000 | I32: =SUM(H32+I31) -> 2240000 | J32: =G32/I32 -> 0.78883929 | K32: =G32-I32 -> -473000 | L32: =D32/SUM(M32:O32) -> #DIV/0! | M32: ='シフト'!N146 -> 0 | N32: ='シフト'!O146 -> 0 | O32: ='シフト'!P146 -> 0
D33: ='シフト'!J152 -> 0 | E33: ='シフト'!K152 -> 0 | F33: =D33-E33 -> 0 | G33: =SUM(D33+G32) -> 1767000 | H33: 80000 | I33: =SUM(H33+I32) -> 2320000 | J33: =G33/I33 -> 0.76163793 | K33: =G33-I33 -> -553000 | L33: =D33/SUM(M33:O33) -> #DIV/0! | M33: ='シフト'!N151 -> 0 | N33: ='シフト'!O151 -> 0 | O33: ='シフト'!P151 -> 0
D34: ='シフト'!J157 -> 0 | E34: ='シフト'!K157 -> 0 | F34: =D34-E34 -> 0 | G34: =G33+D34 -> 1767000 | H34: 80000 | I34: =H34+I33 -> 2400000 | J34: =G34/I34 -> 0.73625 | K34: =G34-I34 -> -633000 | L34: =D34/SUM(M34:O34) -> 0 | M34: ='シフト'!N156 -> 0 | N34: ='シフト'!O156 -> 0 | O34: ='シフト'!P156 -> 1
B35: 月合計 | D35: =SUM(D4:D34) -> 1767000 | E35: =SUM(E4:E34) -> 985093 | F35: =SUM(D35-E35) -> 781907 | G35: =SUM(G34) -> 1767000 | H35: =SUM(H4:H34) -> 2400000 | I35: =I34 -> 2400000 | L35: =AVERAGEIF(L4:L34,"<>#DIV/0!") -> 13090.792 | M35: =SUM(M4:M34) -> 13 | N35: =SUM(N4:N34) -> 68 | O35: =SUM(O4:O34) -> 14532
I36: =I35+'【蒲田】売上'!I35+'【巣鴨】売上'!I35 -> 6740000 | M36: =M35/(M35+N35+O35) -> 0.00088961883 | N36: =N35/(M35+N35+O35) -> 0.0046533908 | O36: =O35/(M35+N35+O35) -> 0.99445699

Sheet シフト
D1: エステムプラザ501 | I1: スカイコート806
E2: 売上 | F2: 取り分 | G2: 粗利 | J2: 売上 | K2: 取り分 | L2: 粗利
A3: 1 | B3: ='【大井町】売上'!C4 -> 日 | C3: 早番 | D3: ='管理シフト'!D6 -> えみり | G3: =E3-F3 -> 0 | I3: ='管理シフト'!G6 -> みこ | L3: =J3-K3 -> 0
D4: 新規/顧客/指名 | I4: 新規/顧客/指名
C5: 遅番 | D5: ='管理シフト'!D7 -> しおん | G5: =E5-F5 -> 0 | I5: ='管理シフト'!G7 -> あんず | L5: =J5-K5 -> 0 | N5: 新規 | O5: 顧客 | P5: 指名
D6: 新規/顧客/指名 | I6: 新規/顧客/指名 | N6: =E4+E6+J4+J6 -> 0 | O6: =F4+F6+K4+K6 -> 0 | P6: =G4+G6+L4+L6 -> 0
J7: =E3+E5+J3+J5 -> 0 | K7: =F3+F5+K3+K5 -> 0 | L7: =SUM(G3+G5+L3+L5+Q3+Q5) -> 0
A8: 2 | B8: ='【大井町】売上'!C5 -> 月 | C8: 早番 | D8: ='管理シフト'!D9 -> ゆかり | G8: =E8-F8 -> 0 | I8: ='管理シフト'!G9 -> かずは | J8: 56000 | K8: 31000 | L8: =J8-K8 -> 25000
D9: 新規/顧客/指名 | I9: 新規/顧客/指名 | J9: 0 | K9: 3 | L9: 0
C10: 遅番 | D10: ='管理シフト'!D10 -> えみり | E10: 18000 | F10: 10000 | G10: =E10-F10 -> 8000 | I10: ='管理シフト'!G10 -> すみれ | L10: =J10-K10 -> 0 | N10: 新規 | O10: 顧客 | P10: 指名
D11: 新規/顧客/指名 | E11: 0 | F11: 1 | G11: 0 | I11: 新規/顧客/指名 | N11: =E9+E11+J9+J11 -> 0 | O11: =F9+F11+K9+K11 -> 4 | P11: =G9+G11+L9+L11 -> 0
J12: =E8+E10+J8+J10 -> 74000 | K12: =F8+F10+K8+K10 -> 41000 | L12: =SUM(G8+G10+L8+L10+Q8+Q10) -> 33000
A13: 3 | B13: ='【大井町】売上'!C6 -> 火 | C13: 早番 | D13: ='管理シフト'!D12 | E13: 26000 | F13: 13000 | G13: =E13-F13 -> 13000 | I13: ='管理シフト'!G12 -> ひより | L13: =J13-K13 -> 0
D14: 新規/顧客/指名 | E14: 0 | F14: 2 | G14: 0 | I14: 新規/顧客/指名
C15: 遅番 | D15: ='管理シフト'!D13 -> しのぶ | G15: =E15-F15 -> 0 | I15: ='管理シフト'!G13 | J15: 64000 | K15: 34500 | L15: =J15-K15 -> 29500 | N15: 新規 | O15: 顧客 | P15: 指名
D16: 新規/顧客/指名 | I16: 新規/顧客/指名 | J16: 0 | K16: 2 | L16: 0 | M16: 1 | N16: =E14+E16+J14+J16 -> 0 | O16: =F14+F16+K14+K16 -> 4 | P16: =G14+G16+L14+L16 -> 0
J17: =E13+E15+J13+J15 -> 90000 | K17: =F13+F15+K13+K15 -> 47500 | L17: =SUM(G13+G15+L13+L15+Q13+Q15) -> 42500
A18: 4 | B18: ='【大井町】売上'!C7 -> 水 | C18: 早番 | D18: ='管理シフト'!D15 | E18: 55000 | F18: 31000 | G18: =E18-F18 -> 24000 | I18: ='管理シフト'!G15 -> てるみ | J18: 43000 | K18: 23500 | L18: =J18-K18 -> 19500
D19: 新規/顧客/指名 | E19: 0 | F19: 2 | G19: 1 | I19: 新規/顧客/指名 | J19: 2 | K19: 1 | L19: 0
C20: 遅番 | D20: ='管理シフト'!D16 -> かすみ | E20: 20000 | F20: 12000 | G20: =E20-F20 -> 8000 | I20: ='管理シフト'!G16 -> えりか | L20: =J20-K20 -> 0 | N20: 新規 | O20: 顧客 | P20: 指名
D21: 新規/顧客/指名 | E21: 0 | F21: 0 | G21: 1 | I21: 新規/顧客/指名 | N21: =E19+E21+J19+J21 -> 2 | O21: =F19+F21+K19+K21 -> 3 | P21: =G19+G21+L19+L21 -> 2
J22: =E18+E20+J18+J20 -> 118000 | K22: =F18+F20+K18+K20 -> 66500 | L22: =SUM(G18+G20+L18+L20+Q18+Q20) -> 51500
A23: 5 | B23: ='【大井町】売上'!C8 -> 木 | C23: 早番 | D23: ='管理シフト'!D18 -> ますみ | E23: 95000 | F23: 57000 | G23: =E23-F23 -> 38000 | I23: ='管理シフト'!G18 | L23: =J23-K23 -> 0
D24: 新規/顧客/指名 | E24: 0 | F24: 2 | G24: 3 | I24: 新規/顧客/指名
C25: 遅番 | D25: ='管理シフト'!D19 -> ののは | G25: =E25-F25 -> 0 | I25: ='管理シフト'!G19 -> しおん | J25: 36000 | K25: 20000 | L25: =J25-K25 -> 16000 | N25: 新規 | O25: 顧客 | P25: 指名
D26: 新規/顧客/指名 | I26: 新規/顧客/指名 | J26: 1 | K26: 1 | L26: 0 | N26: =E24+E26+J24+J26 -> 1 | O26: =F24+F26+K24+K26 -> 3 | P26: =G24+G26+L24+L26 -> 3
J27: =E23+E25+J23+J25 -> 131000 | K27: =F23+F25+K23+K25 -> 77000 | L27: =SUM(G23+G25+L23+L25+Q23+Q25) -> 54000
A28: 6 | B28: ='【大井町】売上'!C9 -> 金 | C28: 早番 | D28: ='管理シフト'!D21 | E28: 17000 | F28: 11000 | G28: =E28-F28 -> 6000 | I28: ='管理シフト'!G21 -> ちなつ | L28: =J28-K28 -> 0
D29: 新規/顧客/指名 | E29: 0 | F29: 0 | G29: 1 | I29: 新規/顧客/指名
C30: 遅番 | D30: ='管理シフト'!D22 -> しずか | E30: 14000 | F30: 8000 | G30: =E30-F30 -> 6000 | I30: ='管理シフト'!G22 -> すみれ | J30: 26000 | K30: 14000 | L30: =J30-K30 -> 12000 | N30: 新規 | O30: 顧客 | P30: 指名
D31: 新規/顧客/指名 | E31: 0 | F31: 1 | G31: 0 | I31: 新規/顧客/指名 | J31: 1 | K31: 1 | L31: 0 | N31: =E29+E31+J29+J31 -> 1 | O31: =F29+F31+K29+K31 -> 2 | P31: =G29+G31+L29+L31 -> 1
J32: =E28+E30+J28+J30 -> 57000 | K32: =F28+F30+K28+K30 -> 33000 | L32: =SUM(G28+G30+L28+L30+Q28+Q30) -> 24000
A33: 7 | B33: ='【大井町】売上'!C10 -> 土 | C33: 早番 | D33: ='管理シフト'!D24 -> ゆかり | E33: 61000 | F33: 33500 | G33: =E33-F33 -> 27500 | I33: ='管理シフト'!G24 -> くれは | J33: 60000 | K33: 27000 | L33: =J33-K33 -> 33000
D34: 新規/顧客/指名 | E34: 0 | F34: 3 | G34: 0 | I34: 新規/顧客/指名 | J34: 2 | K34: 2 | L34: 0
C35: 遅番 | D35: ='管理シフト'!D25 -> わか | E35: 20000 | F35: 11000 | G35: =E35-F35 -> 9000 | I35: ='管理シフト'!G25 | J35: 25000 | K35: 13500 | L35: =J35-K35 -> 11500 | N35: 新規 | O35: 顧客 | P35: 指名
D36: 新規/顧客/指名 | E36: 0 | F36: 1 | G36: 0 | I36: 新規/顧客/指名 | J36: 1 | K36: 1 | L36: 0 | N36: =E34+E36+J34+J36 -> 3 | O36: =F34+F36+K34+K36 -> 7 | P36: =G34+G36+L34+L36 -> 0
J37: =E33+E35+J33+J35 -> 166000 | K37: =F33+F35+K33+K35 -> 85000 | L37: =SUM(G33+G35+L33+L35+Q33+Q35) -> 81000
A38: 8 | B38: ='【大井町】売上'!C11 -> 日 | C38: 早番 | D38: ='管理シフト'!D27 | E38: 43000 | F38: 23000 | G38: =E38-F38 -> 20000 | I38: ='管理シフト'!G27 | J38: 36000 | K38: 21000 | L38: =J38-K38 -> 15000
D39: 新規/顧客/指名 | E39: 0 | F39: 0 | G39: 3 | I39: 新規/顧客/指名 | J39: 0 | K39: 1 | L39: 1
C40: 遅番 | D40: ='管理シフト'!D28 -> ののは | E40: 69000 | F40: 39500 | G40: =E40-F40 -> 29500 | I40: ='管理シフト'!G28 -> しおん | L40: =J40-K40 -> 0 | N40: 新規 | O40: 顧客 | P40: 指名
...

Sheet 【蒲田】売上
B2: ='【大井町】売上'!B1 -> 46054
B3: 日時 | C3: 曜日 | D3: 実績 | E3: 取り分 | F3: 粗利 | G3: 実績累計 | H3: 予算 | I3: 予算累計 | K3: 差異 | L3: 客単価 | M3: 新規 | N3: 顧客 | O3: 指名
B4: ='【大井町】売上'!B4 -> 46054 | C4: ='【大井町】売上'!C4 -> 日 | D4: ='シフト2'!J7 -> 0 | E4: ='シフト2'!K7 -> 0 | F4: =D4-E4 -> 0 | G4: =SUM(D4) -> 0 | H4: 80000 | I4: =H4 -> 80000 | J4: =G4/I4 -> 0 | K4: =G4-I4 -> -80000 | L4: =D4/SUM(M4:O4) -> #DIV/0! | M4: ='シフト2'!N6 -> 0 | N4: ='シフト2'!O6 -> 0 | O4: ='シフト2'!P6 -> 0
B5: ='【大井町】売上'!B5 -> 46055 | C5: ='【大井町】売上'!C5 -> 月 | D5: ='シフト2'!J12 -> 82000 | E5: ='シフト2'!K12 -> 44500 | F5: =D5-E5 -> 37500 | G5: =SUM(D5+G4) -> 82000 | H5: 80000 | I5: =H5+I4 -> 160000 | J5: =G5/I5 -> 0.5125 | K5: =G5-I5 -> -78000 | L5: =D5/SUM(M5:O5) -> 16400 | M5: ='シフト2'!N11 -> 1 | N5: ='シフト2'!O11 -> 2 | O5: ='シフト2'!P11 -> 2
B6: ='【大井町】売上'!B6 -> 46056 | C6: ='【大井町】売上'!C6 -> 火 | D6: ='シフト2'!J17 -> 60000 | E6: ='シフト2'!K17 -> 34000 | F6: =D6-E6 -> 26000 | G6: =SUM(D6+G5) -> 142000 | H6: 80000 | I6: =H6+I5 -> 240000 | J6: =G6/I6 -> 0.59166667 | K6: =G6-I6 -> -98000 | L6: =D6/SUM(M6:O6) -> 15000 | M6: ='シフト2'!N16 -> 0 | N6: ='シフト2'!O16 -> 4 | O6: ='シフト2'!P16 -> 0
B7: ='【大井町】売上'!B7 -> 46057 | C7: ='【大井町】売上'!C7 -> 水 | D7: ='シフト2'!J22 -> 62000 | E7: ='シフト2'!K22 -> 35000 | F7: =D7-E7 -> 27000 | G7: =SUM(D7+G6) -> 204000 | H7: 80000 | I7: =H7+I6 -> 320000 | J7: =G7/I7 -> 0.6375 | K7: =G7-I7 -> -116000 | L7: =D7/SUM(M7:O7) -> 15500 | M7: ='シフト2'!N21 -> 1 | N7: ='シフト2'!O21 -> 3 | O7: ='シフト2'!P21 -> 0
B8: ='【大井町】売上'!B8 -> 46058 | C8: ='【大井町】売上'!C8 -> 木 | D8: ='シフト2'!J27 -> 89000 | E8: ='シフト2'!K27 -> 50925 | F8: =D8-E8 -> 38075 | G8: =SUM(D8+G7) -> 293000 | H8: 80000 | I8: =H8+I7 -> 400000 | J8: =G8/I8 -> 0.7325 | K8: =G8-I8 -> -107000 | L8: =D8/SUM(M8:O8) -> 14833.333 | M8: ='シフト2'!N26 -> 0 | N8: ='シフト2'!O26 -> 5 | O8: ='シフト2'!P26 -> 1
B9: ='【大井町】売上'!B9 -> 46059 | C9: ='【大井町】売上'!C9 -> 金 | D9: ='シフト2'!J32 -> 86000 | E9: ='シフト2'!K32 -> 45099 | F9: =D9-E9 -> 40901 | G9: =SUM(D9+G8) -> 379000 | H9: 80000 | I9: =H9+I8 -> 480000 | J9: =G9/I9 -> 0.78958333 | K9: =G9-I9 -> -101000 | L9: =D9/SUM(M9:O9) -> 17200 | M9: ='シフト2'!N31 -> 0 | N9: ='シフト2'!O31 -> 4 | O9: ='シフト2'!P31 -> 1
B10: ='【大井町】売上'!B10 -> 46060 | C10: ='【大井町】売上'!C10 -> 土 | D10: ='シフト2'!J37 -> 59000 | E10: ='シフト2'!K37 -> 34447 | F10: =D10-E10 -> 24553 | G10: =SUM(D10+G9) -> 438000 | H10: 80000 | I10: =H10+I9 -> 560000 | J10: =G10/I10 -> 0.78214286 | K10: =G10-I10 -> -122000 | L10: =D10/SUM(M10:O10) -> 14750 | M10: ='シフト2'!N36 -> 3 | N10: ='シフト2'!O36 -> 1 | O10: ='シフト2'!P36 -> 0
A11: =SUM(D4:D10) -> 438000 | B11: ='【大井町】売上'!B11 -> 46061 | C11: ='【大井町】売上'!C11 -> 日 | D11: ='シフト2'!J42 -> 30000 | E11: ='シフト2'!K42 -> 17000 | F11: =D11-E11 -> 13000 | G11: =SUM(D11+G10) -> 468000 | H11: 80000 | I11: =H11+I10 -> 640000 | J11: =G11/I11 -> 0.73125 | K11: =G11-I11 -> -172000 | L11: =D11/SUM(M11:O11) -> 15000 | M11: ='シフト2'!N41 -> 1 | N11: ='シフト2'!O41 -> 1 | O11: ='シフト2'!P41 -> 0
B12: ='【大井町】売上'!B12 -> 46062 | C12: ='【大井町】売上'!C12 -> 月 | D12: ='シフト2'!J47 -> 138000 | E12: ='シフト2'!K47 -> 77000 | F12: =D12-E12 -> 61000 | G12: =SUM(D12+G11) -> 606000 | H12: 80000 | I12: =H12+I11 -> 720000 | J12: =G12/I12 -> 0.84166667 | K12: =G12-I12 -> -114000 | L12: =D12/SUM(M12:O12) -> 17250 | M12: ='シフト2'!N46 -> 1 | N12: ='シフト2'!O46 -> 6 | O12: ='シフト2'!P46 -> 1
B13: ='【大井町】売上'!B13 -> 46063 | C13: ='【大井町】売上'!C13 -> 火 | D13: ='シフト2'!J52 -> 112000 | E13: ='シフト2'!K52 -> 61000 | F13: =D13-E13 -> 51000 | G13: =SUM(D13+G12) -> 718000 | H13: 80000 | I13: =H13+I12 -> 800000 | J13: =G13/I13 -> 0.8975 | K13: =G13-I13 -> -82000 | L13: =D13/SUM(M13:O13) -> 18666.667 | M13: ='シフト2'!N51 -> 3 | N13: ='シフト2'!O51 -> 3 | O13: ='シフト2'!P51 -> 0
B14: ='【大井町】売上'!B14 -> 46064 | C14: ='【大井町】売上'!C14 -> 水 | D14: ='シフト2'!J57 -> 73000 | E14: ='シフト2'!K57 -> 38500 | F14: =D14-E14 -> 34500 | G14: =SUM(D14+G13) -> 791000 | H14: 80000 | I14: =H14+I13 -> 880000 | J14: =G14/I14 -> 0.89886364 | K14: =G14-I14 -> -89000 | L14: =D14/SUM(M14:O14) -> 18250 | M14: ='シフト2'!N56 -> 1 | N14: ='シフト2'!O56 -> 3 | O14: ='シフト2'!P56 -> 0
B15: ='【大井町】売上'!B15 -> 46065 | C15: ='【大井町】売上'!C15 -> 木 | D15: ='シフト2'!J62 -> 97000 | E15: ='シフト2'!K62 -> 56847 | F15: =D15-E15 -> 40153 | G15: =SUM(D15+G14) -> 888000 | H15: 80000 | I15: =H15+I14 -> 960000 | J15: =G15/I15 -> 0.925 | K15: =G15-I15 -> -72000 | L15: =D15/SUM(M15:O15) -> 16166.667 | M15: ='シフト2'!N61 -> 0 | N15: ='シフト2'!O61 -> 4 | O15: ='シフト2'!P61 -> 2
B16: ='【大井町】売上'!B16 -> 46066 | C16: ='【大井町】売上'!C16 -> 金 | D16: ='シフト2'!J67 -> 51000 | E16: ='シフト2'!K67 -> 29000 | F16: =D16-E16 -> 22000 | G16: =SUM(D16+G15) -> 939000 | H16: 80000 | I16: =H16+I15 -> 1040000 | J16: =G16/I16 -> 0.90288462 | K16: =G16-I16 -> -101000 | L16: =D16/SUM(M16:O16) -> 17000 | M16: ='シフト2'!N66 -> 0 | N16: ='シフト2'!O66 -> 1 | O16: ='シフト2'!P66 -> 2
B17: ='【大井町】売上'!B17 -> 46067 | C17: ='【大井町】売上'!C17 -> 土 | D17: ='シフト2'!J72 -> 64000 | E17: ='シフト2'!K72 -> 40822 | F17: =D17-E17 -> 23178 | G17: =SUM(D17+G16) -> 1003000 | H17: 80000 | I17: =H17+I16 -> 1120000 | J17: =G17/I17 -> 0.89553571 | K17: =G17-I17 -> -117000 | L17: =D17/SUM(M17:O17) -> 21333.333 | M17: ='シフト2'!N71 -> 0 | N17: ='シフト2'!O71 -> 3 | O17: ='シフト2'!P71 -> 0
A18: =SUM(D11:D17) -> 565000 | B18: ='【大井町】売上'!B18 -> 46068 | C18: ='【大井町】売上'!C18 -> 日 | D18: ='シフト2'!J77 -> 68000 | E18: ='シフト2'!K77 -> 35000 | F18: =D18-E18 -> 33000 | G18: =SUM(D18+G17) -> 1071000 | H18: 80000 | I18: =H18+I17 -> 1200000 | J18: =G18/I18 -> 0.8925 | K18: =G18-I18 -> -129000 | L18: =D18/SUM(M18:O18) -> 17000 | M18: ='シフト2'!N76 -> 0 | N18: ='シフト2'!O76 -> 3 | O18: ='シフト2'!P76 -> 1
B19: ='【大井町】売上'!B19 -> 46069 | C19: ='【大井町】売上'!C19 -> 月 | D19: ='シフト2'!J82 -> 92000 | E19: ='シフト2'!K82 -> 52500 | F19: =D19-E19 -> 39500 | G19: =SUM(D19+G18) -> 1163000 | H19: 80000 | I19: =H19+I18 -> 1280000 | J19: =G19/I19 -> 0.90859375 | K19: =G19-I19 -> -117000 | L19: =D19/SUM(M19:O19) -> 18400 | M19: ='シフト2'!N81 -> 0 | N19: ='シフト2'!O81 -> 3 | O19: ='シフト2'!P81 -> 2
B20: ='【大井町】売上'!B20 -> 46070 | C20: ='【大井町】売上'!C20 -> 火 | D20: ='シフト2'!J87 -> 90000 | E20: ='シフト2'!K87 -> 53600 | F20: =D20-E20 -> 36400 | G20: =SUM(D20+G19) -> 1253000 | H20: 80000 | I20: =H20+I19 -> 1360000 | J20: =G20/I20 -> 0.92132353 | K20: =G20-I20 -> -107000 | L20: =D20/SUM(M20:O20) -> 15000 | M20: ='シフト2'!N86 -> 1 | N20: ='シフト2'!O86 -> 5 | O20: ='シフト2'!P86 -> 0
B21: ='【大井町】売上'!B21 -> 46071 | C21: ='【大井町】売上'!C21 -> 水 | D21: ='シフト2'!J92 -> 63000 | E21: ='シフト2'!K92 -> 36500 | F21: =D21-E21 -> 26500 | G21: =SUM(D21+G20) -> 1316000 | H21: 80000 | I21: =H21+I20 -> 1440000 | J21: =G21/I21 -> 0.91388889 | K21: =G21-I21 -> -124000 | L21: =D21/SUM(M21:O21) -> 15750 | M21: ='シフト2'!N91 -> 0 | N21: ='シフト2'!O91 -> 3 | O21: ='シフト2'!P91 -> 1
B22: ='【大井町】売上'!B22 -> 46072 | C22: ='【大井町】売上'!C22 -> 木 | D22: ='シフト2'!J97 -> 79000 | E22: ='シフト2'!K97 -> 45764 | F22: =D22-E22 -> 33236 | G22: =SUM(D22+G21) -> 1395000 | H22: 80000 | I22: =H22+I21 -> 1520000 | J22: =G22/I22 -> 0.91776316 | K22: =G22-I22 -> -125000 | L22: =D22/SUM(M22:O22) -> 15800 | M22: ='シフト2'!N96 -> 1 | N22: ='シフト2'!O96 -> 4 | O22: ='シフト2'!P96 -> 0
B23: ='【大井町】売上'!B23 -> 46073 | C23: ='【大井町】売上'!C23 -> 金 | D23: ='シフト2'!J102 -> 60000 | E23: ='シフト2'!K102 -> 33349 | F23: =D23-E23 -> 26651 | G23: =SUM(D23+G22) -> 1455000 | H23: 80000 | I23: =H23+I22 -> 1600000 | J23: =G23/I23 -> 0.909375 | K23: =G23-I23 -> -145000 | L23: =D23/SUM(M23:O23) -> 15000 | M23: ='シフト2'!N101 -> 0 | N23: ='シフト2'!O101 -> 2 | O23: ='シフト2'!P101 -> 2
B24: ='【大井町】売上'!B24 -> 46074 | C24: ='【大井町】売上'!C24 -> 土 | D24: ='シフト2'!J107 -> 46000 | E24: ='シフト2'!K107 -> 26000 | F24: =D24-E24 -> 20000 | G24: =SUM(D24+G23) -> 1501000 | H24: 80000 | I24: =H24+I23 -> 1680000 | J24: =G24/I24 -> 0.89345238 | K24: =G24-I24 -> -179000 | L24: =D24/SUM(M24:O24) -> 15333.333 | M24: ='シフト2'!N106 -> 2 | N24: ='シフト2'!O106 -> 0 | O24: ='シフト2'!P106 -> 1
A25: =SUM(D18:D24) -> 498000 | B25: ='【大井町】売上'!B25 -> 46075 | C25: ='【大井町】売上'!C25 -> 日 | D25: ='シフト2'!J112 -> 66000 | E25: ='シフト2'!K112 -> 35000 | F25: =D25-E25 -> 31000 | G25: =SUM(D25+G24) -> 1567000 | H25: 80000 | I25: =H25+I24 -> 1760000 | J25: =G25/I25 -> 0.89034091 | K25: =G25-I25 -> -193000 | L25: =D25/SUM(M25:O25) -> 13200 | M25: ='シフト2'!N111 -> 3 | N25: ='シフト2'!O111 -> 2 | O25: ='シフト2'!P111 -> 0
B26: ='【大井町】売上'!B26 -> 46076 | C26: ='【大井町】売上'!C26 -> 月 | D26: ='シフト2'!J117 -> 0 | E26: ='シフト2'!K117 -> 0 | F26: =D26-E26 -> 0 | G26: =SUM(D26+G25) -> 1567000 | H26: 80000 | I26: =H26+I25 -> 1840000 | J26: =G26/I26 -> 0.85163043 | K26: =G26-I26 -> -273000 | L26: =D26/SUM(M26:O26) -> #DIV/0! | M26: ='シフト2'!N116 -> 0 | N26: ='シフト2'!O116 -> 0 | O26: ='シフト2'!P116 -> 0
B27: ='【大井町】売上'!B27 -> 46077 | C27: ='【大井町】売上'!C27 -> 火 | D27: ='シフト2'!J122 -> 0 | E27: ='シフト2'!K122 -> 0 | F27: =D27-E27 -> 0 | G27: =SUM(D27+G26) -> 1567000 | H27: 80000 | I27: =H27+I26 -> 1920000 | J27: =G27/I27 -> 0.81614583 | K27: =G27-I27 -> -353000 | L27: =D27/SUM(M27:O27) -> #DIV/0! | M27: ='シフト2'!N121 -> 0 | N27: ='シフト2'!O121 -> 0 | O27: ='シフト2'!P121 -> 0
B28: ='【大井町】売上'!B28 -> 46078 | C28: ='【大井町】売上'!C28 -> 水 | D28: ='シフト2'!J127 -> 0 | E28: ='シフト2'!K127 -> 0 | F28: =D28-E28 -> 0 | G28: =SUM(D28+G27) -> 1567000 | H28: 80000 | I28: =H28+I27 -> 2000000 | J28: =G28/I28 -> 0.7835 | K28: =G28-I28 -> -433000 | L28: =D28/SUM(M28:O28) -> #DIV/0! | M28: ='シフト2'!N126 -> 0 | N28: ='シフト2'!O126 -> 0 | O28: ='シフト2'!P126 -> 0
B29: ='【大井町】売上'!B29 -> 46079 | C29: ='【大井町】売上'!C29 -> 木 | D29: ='シフト2'!J132 -> 0 | E29: ='シフト2'!K132 -> 0 | F29: =D29-E29 -> 0 | G29: =SUM(D29+G28) -> 1567000 | H29: 80000 | I29: =H29+I28 -> 2080000 | J29: =G29/I29 -> 0.75336538 | K29: =G29-I29 -> -513000 | L29: =D29/SUM(M29:O29) -> #DIV/0! | M29: ='シフト2'!N131 -> 0 | N29: ='シフト2'!O131 -> 0 | O29: ='シフト2'!P131 -> 0
B30: ='【大井町】売上'!B30 -> 46080 | C30: ='【大井町】売上'!C30 -> 金 | D30: ='シフト2'!J137 -> 0 | E30: ='シフト2'!K137 -> 0 | F30: =D30-E30 -> 0 | G30: =SUM(D30+G29) -> 1567000 | H30: 80000 | I30: =H30+I29 -> 2160000 | J30: =G30/I30 -> 0.72546296 | K30: =G30-I30 -> -593000 | L30: =D30/SUM(M30:O30) -> #DIV/0! | M30: ='シフト2'!N136 -> 0 | N30: ='シフト2'!O136 -> 0 | O30: ='シフト2'!P136 -> 0
B31: ='【大井町】売上'!B31 -> 46081 | C31: ='【大井町】売上'!C31 -> 土 | D31: ='シフト2'!J142 -> 0 | E31: ='シフト2'!K142 -> 0 | F31: =D31-E31 -> 0 | G31: =SUM(D31+G30) -> 1567000 | H31: 80000 | I31: =H31+I30 -> 2240000 | J31: =G31/I31 -> 0.69955357 | K31: =G31-I31 -> -673000 | L31: =D31/SUM(M31:O31) -> #DIV/0! | M31: ='シフト2'!N141 -> 0 | N31: ='シフト2'!O141 -> 0 | O31: ='シフト2'!P141 -> 0
A32: =SUM(D25:D31) -> 66000 | B32: ='【大井町】売上'!B32 | C32: ='【大井町】売上'!C32 | D32: ='シフト2'!J147 -> 0 | E32: ='シフト2'!K147 -> 0 | F32: =D32-E32 -> 0 | G32: =SUM(D32+G31) -> 1567000 | H32: 80000 | I32: =H32+I31 -> 2320000 | J32: =G32/I32 -> 0.67543103 | K32: =G32-I32 -> -753000 | L32: =D32/SUM(M32:O32) -> #DIV/0! | M32: ='シフト2'!N146 -> 0 | N32: ='シフト2'!O146 -> 0 | O32: ='シフト2'!P146 -> 0
A33: =SUM(D27:D33) -> 0 | B33: ='【大井町】売上'!B33 | C33: ='【大井町】売上'!C33 | D33: ='シフト2'!J152 -> 0 | E33: ='シフト2'!K152 -> 0 | F33: =D33-E33 -> 0 | G33: =SUM(D33+G32) -> 1567000 | H33: 80000 | I33: =H33+I32 -> 2400000 | J33: =G33/I33 -> 0.65291667 | K33: =G33-I33 -> -833000 | L33: =D33/SUM(M33:O33) -> #DIV/0! | M33: ='シフト2'!N151 -> 0 | N33: ='シフト2'!O151 -> 0 | O33: ='シフト2'!P151 -> 0
B34: ='【大井町】売上'!B34 | C34: ='【大井町】売上'!C34 | D34: ='シフト2'!J157 -> 0 | E34: ='シフト2'!K157 -> 0 | F34: =D34-E34 -> 0 | G34: =G33+D34 -> 1567000 | H34: 80000 | I34: =H34+I33 -> 2480000 | J34: =G34/I34 -> 0.63185484 | K34: =G34-I34 -> -913000 | L34: =D34/SUM(M34:O34) -> #DIV/0! | M34: ='シフト2'!N156 -> 0 | N34: ='シフト2'!O156 -> 0 | O34: ='シフト2'!P156 -> 0
B35: 月合計 | D35: =SUM(D4:D34) -> 1567000 | E35: =SUM(E4:E34) -> 881853 | F35: =SUM(D35-E35) -> 685147 | G35: =SUM(G34) -> 1567000 | H35: =SUM(H4:H34) -> 2480000 | I35: =H35 -> 2480000 | K35: 0 | L35: =AVERAGEIF(L4:L34,"<>#DIV/0!") -> 16325.397 | M35: =SUM(M4:M33) -> 18 | N35: =SUM(N4:N34) -> 62 | O35: =SUM(O4:O34) -> 16
M36: =M35/(M35+N35+O35) -> 0.1875 | N36: =N35/(M35+N35+O35) -> 0.64583333 | O36: =O35/(M35+N35+O35) -> 0.16666667

Sheet シフト2
D1: エルデューチェ303 | H1: レジディア1001
E2: 売上 | F2: 取り分 | G2: 粗利 | J2: 売上 | K2: 取り分 | L2: 粗利
A3: 1 | B3: ='【大井町】売上'!C4 -> 日 | C3: 早番 | D3: ='管理シフト'!J6 -> やすの | G3: =E3-F3 -> 0 | I3: ='管理シフト'!M6 -> まな | L3: =J3-K3 -> 0
D4: 新規/顧客/指名 | I4: 新規/顧客/指名
C5: 遅番 | D5: ='管理シフト'!J7 -> ののは | G5: =E5-F5 -> 0 | I5: ='管理シフト'!M7 | L5: =J5-K5 -> 0 | N5: 新規 | O5: 顧客 | P5: 指名
D6: 新規/顧客/指名 | I6: 新規/顧客/指名 | N6: =E4+E6+J4+J6 -> 0 | O6: =F4+F6+K4+K6 -> 0 | P6: =G4+G6+L4+L6 -> 0
J7: =E3+E5+J3+J5 -> 0 | K7: =F3+F5+K3+K5 -> 0 | L7: =SUM(G3+G5+L3+L5+Q3+Q5) -> 0
A8: 2 | B8: ='【大井町】売上'!C5 -> 月 | C8: 早番 | D8: ='管理シフト'!J9 | E8: 43000 | F8: 25000 | G8: =E8-F8 -> 18000 | I8: ='管理シフト'!M9 -> ちひろ | J8: 39000 | K8: 19500 | L8: =J8-K8 -> 19500
D9: 新規/顧客/指名 | E9: 0 | F9: 1 | G9: 2 | I9: 新規/顧客/指名 | J9: 1 | K9: 1 | L9: 0
C10: 遅番 | D10: ='管理シフト'!J10 -> しおん | G10: =E10-F10 -> 0 | I10: ='管理シフト'!M10 -> えりか | L10: =J10-K10 -> 0 | O10: 顧客 | P10: 指名
D11: 新規/顧客/指名 | I11: 新規/顧客/指名 | N11: =E9+E11+J9+J11 -> 1 | O11: =F9+F11+K9+K11 -> 2 | P11: =G9+G11+L9+L11 -> 2
J12: =E8+E10+J8+J10 -> 82000 | K12: =F8+F10+K8+K10 -> 44500 | L12: =SUM(G8+G10+L8+L10+Q8+Q10) -> 37500
A13: 3 | B13: ='【大井町】売上'!C6 -> 火 | C13: 早番 | D13: ='管理シフト'!J12 -> ますみ | E13: 20000 | F13: 11000 | G13: =E13-F13 -> 9000 | I13: ='管理シフト'!M12 -> てるみ | J13: 0 | K13: 0 | L13: =J13-K13 -> 0 | S13: x
D14: 新規/顧客/指名 | E14: 0 | F14: 1 | G14: 0 | I14: 新規/顧客/指名
C15: 遅番 | D15: ='管理シフト'!J13 -> すみれ | E15: 40000 | F15: 23000 | G15: =E15-F15 -> 17000 | I15: ='管理シフト'!M13 | L15: =J15-K15 -> 0 | N15: 新規 | O15: 顧客 | P15: 指名
D16: 新規/顧客/指名 | E16: 0 | F16: 3 | G16: 0 | I16: 新規/顧客/指名 | N16: =E14+E16+J14+J16 -> 0 | O16: =F14+F16+K14+K16 -> 4 | P16: =G14+G16+L14+L16 -> 0
J17: =E13+E15+J13+J15 -> 60000 | K17: =F13+F15+K13+K15 -> 34000 | L17: =SUM(G13+G15+L13+L15+Q13+Q15) -> 26000
A18: 4 | B18: ='【大井町】売上'!C7 -> 水 | C18: 早番 | D18: ='管理シフト'!J15 -> ゆかり | E18: 36000 | F18: 22000 | G18: =E18-F18 -> 14000 | I18: ='管理シフト'!M15 -> くれは | L18: =J18-K18 -> 0
E19: 0 | F19: 2 | G19: 0 | I19: 新規/顧客/指名
C20: 遅番 | D20: ='管理シフト'!J16 -> えみり | G20: =E20-F20 -> 0 | I20: ='管理シフト'!M16 | J20: 26000 | K20: 13000 | L20: =J20-K20 -> 13000 | N20: 新規 | O20: 顧客 | P20: 指名
D21: 新規/顧客/指名 | I21: 新規/顧客/指名 | J21: 1 | K21: 1 | L21: 0 | N21: =E19+E21+J19+J21 -> 1 | O21: =F19+F21+K19+K21 -> 3 | P21: =G19+G21+L19+L21 -> 0
J22: =E18+E20+J18+J20 -> 62000 | K22: =F18+F20+K18+K20 -> 35000 | L22: =SUM(G18+G20+L18+L20+Q18+Q20) -> 27000
A23: 5 | B23: ='【大井町】売上'!C8 -> 木 | C23: 早番 | D23: ='管理シフト'!J18 -> てるみ | E23: 30000 | F23: 17000 | G23: =E23-F23 -> 13000 | I23: ='管理シフト'!M18 -> ちひろ | J23: 45000 | K23: 25925 | L23: =J23-K23 -> 19075
D24: 新規/顧客/指名 | E24: 0 | F24: 2 | G24: 0 | I24: 新規/顧客/指名 | J24: 0 | K24: 3 | L24: 0
C25: 遅番 | D25: ='管理シフト'!J19 | E25: 0 | F25: 0 | G25: =E25-F25 -> 0 | I25: ='管理シフト'!M19 -> かずは | J25: 14000 | K25: 8000 | L25: =J25-K25 -> 6000 | N25: 新規 | O25: 顧客 | P25: 指名
D26: 新規/顧客/指名 | I26: 新規/顧客/指名 | J26: 0 | K26: 0 | L26: 1 | N26: =E24+E26+J24+J26 -> 0 | O26: =F24+F26+K24+K26 -> 5 | P26: =G24+G26+L24+L26 -> 1
J27: =E23+E25+J23+J25 -> 89000 | K27: =F23+F25+K23+K25 -> 50925 | L27: =SUM(G23+G25+L23+L25+Q23+Q25) -> 38075
A28: 6 | B28: ='【大井町】売上'!C9 -> 金 | C28: 早番 | D28: ='管理シフト'!J21 -> まな | E28: 12000 | F28: 6000 | G28: =E28-F28 -> 6000 | I28: ='管理シフト'!M21 -> ちひろ | L28: =J28-K28 -> 0
D29: 新規/顧客/指名 | E29: 0 | F29: 0 | G29: 1 | I29: 新規/顧客/指名
C30: 遅番 | D30: ='管理シフト'!J22 -> えりか | E30: 40000 | F30: 25099 | G30: =E30-F30 -> 14901 | I30: ='管理シフト'!M22 -> しのぶ | J30: 34000 | K30: 14000 | L30: =J30-K30 -> 20000 | N30: 新規 | O30: 顧客 | P30: 指名
D31: 新規/顧客/指名 | E31: 0 | F31: 2 | G31: 0 | I31: 新規/顧客/指名 | J31: 0 | K31: 2 | L31: 0 | N31: =E29+E31+J29+J31 -> 0 | O31: =F29+F31+K29+K31 -> 4 | P31: =G29+G31+L29+L31 -> 1
J32: =E28+E30+J28+J30 -> 86000 | K32: =F28+F30+K28+K30 -> 45099 | L32: =SUM(G28+G30+L28+L30+Q28+Q30) -> 40901
A33: 7 | B33: ='【大井町】売上'!C10 -> 土 | C33: 早番 | D33: ='管理シフト'!J24 -> てるみ | E33: 30000 | F33: 17000 | G33: =E33-F33 -> 13000 | I33: ='管理シフト'!M24 -> くみ | J33: 15000 | K33: 9447 | L33: =J33-K33 -> 5553
D34: 新規/顧客/指名 | E34: 1 | F34: 1 | G34: 0 | I34: 新規/顧客/指名 | J34: 1 | K34: 0 | L34: 0
C35: 遅番 | D35: ='管理シフト'!J25 | G35: =E35-F35 -> 0 | I35: ='管理シフト'!M25 -> かすみ | J35: 14000 | K35: 8000 | L35: =J35-K35 -> 6000 | N35: 新規 | O35: 顧客 | P35: 指名
D36: 新規/顧客/指名 | I36: 新規/顧客/指名 | J36: 1 | K36: 0 | L36: 0 | N36: =E34+E36+J34+J36 -> 3 | O36: =F34+F36+K34+K36 -> 1 | P36: =G34+G36+L34+L36 -> 0
J37: =E33+E35+J33+J35 -> 59000 | K37: =F33+F35+K33+K35 -> 34447 | L37: =SUM(G33+G35+L33+L35+Q33+Q35) -> 24553
A38: 8 | B38: ='【大井町】売上'!C11 -> 日 | C38: 早番 | D38: ='管理シフト'!J27 | E38: 15000 | F38: 8500 | G38: =E38-F38 -> 6500 | I38: ='管理シフト'!M27 -> ひより | L38: =J38-K38 -> 0 | Z38: --
D39: 新規/顧客/指名 | E39: 0 | F39: 1 | G39: 0 | I39: 新規/顧客/指名
C40: 遅番 | D40: ='管理シフト'!J28 -> わか | G40: =E40-F40 -> 0 | I40: ='管理シフト'!M28 | J40: 15000 | K40: 8500 | L40: =J40-K40 -> 6500 | N40: 新規 | O40: 顧客 | P40: 指名
...

Sheet 【巣鴨】売上
B2: ='【大井町】売上'!B1 -> 46054
B3: 日時 | C3: 曜日 | D3: 実績 | E3: 取り分 | F3: 粗利 | G3: 実績累計 | H3: 予算 | I3: 予算累計 | K3: 差異 | L3: 客単価 | M3: 新規 | N3: 顧客 | O3: 指名
B4: ='【大井町】売上'!B4 -> 46054 | C4: ='【大井町】売上'!C4 -> 日 | D4: ='シフト3'!J7 -> 0 | E4: ='シフト3'!K7 -> 0 | F4: =D4-E4 -> 0 | G4: =SUM(D4) -> 0 | H4: 60000 | I4: =H4 -> 60000 | J4: =G4/I4 -> 0 | K4: =G4-I4 -> -60000 | L4: =D4/SUM(M4:O4) -> #DIV/0! | M4: ='シフト2'!N6 -> 0 | N4: ='シフト2'!O6 -> 0 | O4: ='シフト3'!P6 -> 0
B5: ='【大井町】売上'!B5 -> 46055 | C5: ='【大井町】売上'!C5 -> 月 | D5: ='シフト3'!J12 -> 0 | E5: ='シフト3'!K12 -> 0 | F5: =D5-E5 -> 0 | G5: =SUM(D5+G4) -> 0 | H5: 60000 | I5: =H5+I4 -> 120000 | J5: =G5/I5 -> 0 | K5: =G5-I5 -> -120000 | L5: =D5/SUM(M5:O5) -> 0 | M5: ='シフト2'!N11 -> 1 | N5: ='シフト2'!O11 -> 2 | O5: ='シフト3'!P11 -> 0
B6: ='【大井町】売上'!B6 -> 46056 | C6: ='【大井町】売上'!C6 -> 火 | D6: ='シフト3'!J17 -> 74000 | E6: ='シフト3'!K17 -> 42500 | F6: =D6-E6 -> 31500 | G6: =SUM(D6+G5) -> 74000 | H6: 60000 | I6: =H6+I5 -> 180000 | J6: =G6/I6 -> 0.41111111 | K6: =G6-I6 -> -106000 | L6: =D6/SUM(M6:O6) -> 14800 | M6: ='シフト2'!N16 -> 0 | N6: ='シフト2'!O16 -> 4 | O6: ='シフト3'!P16 -> 1
B7: ='【大井町】売上'!B7 -> 46057 | C7: ='【大井町】売上'!C7 -> 水 | D7: ='シフト3'!J22 -> 27000 | E7: ='シフト3'!K22 -> 16000 | F7: =D7-E7 -> 11000 | G7: =SUM(D7+G6) -> 101000 | H7: 60000 | I7: =H7+I6 -> 240000 | J7: =G7/I7 -> 0.42083333 | K7: =G7-I7 -> -139000 | L7: =D7/SUM(M7:O7) -> 6750 | M7: ='シフト2'!N21 -> 1 | N7: ='シフト2'!O21 -> 3 | O7: ='シフト3'!P21 -> 0
B8: ='【大井町】売上'!B8 -> 46058 | C8: ='【大井町】売上'!C8 -> 木 | D8: ='シフト3'!J27 -> 0 | E8: ='シフト3'!K27 -> 0 | F8: =D8-E8 -> 0 | G8: =SUM(D8+G7) -> 101000 | H8: 60000 | I8: =H8+I7 -> 300000 | J8: =G8/I8 -> 0.33666667 | K8: =G8-I8 -> -199000 | L8: =D8/SUM(M8:O8) -> 0 | M8: ='シフト2'!N26 -> 0 | N8: ='シフト2'!O26 -> 5 | O8: ='シフト3'!P26 -> 0
B9: ='【大井町】売上'!B9 -> 46059 | C9: ='【大井町】売上'!C9 -> 金 | D9: ='シフト3'!J32 -> 73000 | E9: ='シフト3'!K32 -> 41000 | F9: =D9-E9 -> 32000 | G9: =SUM(D9+G8) -> 174000 | H9: 60000 | I9: =H9+I8 -> 360000 | J9: =G9/I9 -> 0.48333333 | K9: =G9-I9 -> -186000 | L9: =D9/SUM(M9:O9) -> 18250 | M9: ='シフト2'!N31 -> 0 | N9: ='シフト2'!O31 -> 4 | O9: ='シフト3'!P31 -> 0
B10: ='【大井町】売上'!B10 -> 46060 | C10: ='【大井町】売上'!C10 -> 土 | D10: ='シフト3'!J37 -> 37000 | E10: ='シフト3'!K37 -> 20500 | F10: =D10-E10 -> 16500 | G10: =SUM(D10+G9) -> 211000 | H10: 60000 | I10: =H10+I9 -> 420000 | J10: =G10/I10 -> 0.50238095 | K10: =G10-I10 -> -209000 | L10: =D10/SUM(M10:O10) -> 9250 | M10: ='シフト2'!N36 -> 3 | N10: ='シフト2'!O36 -> 1 | O10: ='シフト3'!P36 -> 0
A11: =SUM(D4:D10) -> 211000 | B11: ='【大井町】売上'!B11 -> 46061 | C11: ='【大井町】売上'!C11 -> 日 | D11: ='シフト3'!J42 -> 49000 | E11: ='シフト3'!K42 -> 28000 | F11: =D11-E11 -> 21000 | G11: =SUM(D11+G10) -> 260000 | H11: 60000 | I11: =H11+I10 -> 480000 | J11: =G11/I11 -> 0.54166667 | K11: =G11-I11 -> -220000 | L11: =D11/SUM(M11:O11) -> 24500 | M11: ='シフト2'!N41 -> 1 | N11: ='シフト2'!O41 -> 1 | O11: ='シフト3'!P41 -> 0
B12: ='【大井町】売上'!B12 -> 46062 | C12: ='【大井町】売上'!C12 -> 月 | D12: ='シフト3'!J47 -> 32000 | E12: ='シフト3'!K47 -> 17500 | F12: =D12-E12 -> 14500 | G12: =SUM(D12+G11) -> 292000 | H12: 60000 | I12: =H12+I11 -> 540000 | J12: =G12/I12 -> 0.54074074 | K12: =G12-I12 -> -248000 | L12: =D12/SUM(M12:O12) -> 4000 | M12: ='シフト2'!N46 -> 1 | N12: ='シフト2'!O46 -> 6 | O12: ='シフト3'!P46 -> 1
B13: ='【大井町】売上'!B13 -> 46063 | C13: ='【大井町】売上'!C13 -> 火 | D13: ='シフト3'!J52 -> 60000 | E13: ='シフト3'!K52 -> 35000 | F13: =D13-E13 -> 25000 | G13: =SUM(D13+G12) -> 352000 | H13: 60000 | I13: =H13+I12 -> 600000 | J13: =G13/I13 -> 0.58666667 | K13: =G13-I13 -> -248000 | L13: =D13/SUM(M13:O13) -> 8571.4286 | M13: ='シフト2'!N51 -> 3 | N13: ='シフト2'!O51 -> 3 | O13: ='シフト3'!P51 -> 1
B14: ='【大井町】売上'!B14 -> 46064 | C14: ='【大井町】売上'!C14 -> 水 | D14: ='シフト3'!J57 -> 35000 | E14: ='シフト3'!K57 -> 21000 | F14: =D14-E14 -> 14000 | G14: =SUM(D14+G13) -> 387000 | H14: 60000 | I14: =H14+I13 -> 660000 | J14: =G14/I14 -> 0.58636364 | K14: =G14-I14 -> -273000 | L14: =D14/SUM(M14:O14) -> 8750 | M14: ='シフト2'!N56 -> 1 | N14: ='シフト2'!O56 -> 3 | O14: ='シフト3'!P56 -> 0
B15: ='【大井町】売上'!B15 -> 46065 | C15: ='【大井町】売上'!C15 -> 木 | D15: ='シフト3'!J62 -> 25000 | E15: ='シフト3'!K62 -> 15000 | F15: =D15-E15 -> 10000 | G15: =SUM(D15+G14) -> 412000 | H15: 60000 | I15: =H15+I14 -> 720000 | J15: =G15/I15 -> 0.57222222 | K15: =G15-I15 -> -308000 | L15: =D15/SUM(M15:O15) -> 6250 | M15: ='シフト2'!N61 -> 0 | N15: ='シフト2'!O61 -> 4 | O15: ='シフト3'!P61 -> 0
B16: ='【大井町】売上'!B16 -> 46066 | C16: ='【大井町】売上'!C16 -> 金 | D16: ='シフト3'!J67 -> 30000 | E16: ='シフト3'!K67 -> 17000 | F16: =D16-E16 -> 13000 | G16: =SUM(D16+G15) -> 442000 | H16: 60000 | I16: =H16+I15 -> 780000 | J16: =G16/I16 -> 0.56666667 | K16: =G16-I16 -> -338000 | L16: =D16/SUM(M16:O16) -> 30000 | M16: ='シフト2'!N66 -> 0 | N16: ='シフト2'!O66 -> 1 | O16: ='シフト3'!P66 -> 0
B17: ='【大井町】売上'!B17 -> 46067 | C17: ='【大井町】売上'!C17 -> 土 | D17: ='シフト3'!J72 -> 12000 | E17: ='シフト3'!K72 -> 7000 | F17: =D17-E17 -> 5000 | G17: =SUM(D17+G16) -> 454000 | H17: 60000 | I17: =H17+I16 -> 840000 | J17: =G17/I17 -> 0.54047619 | K17: =G17-I17 -> -386000 | L17: =D17/SUM(M17:O17) -> 4000 | M17: ='シフト2'!N71 -> 0 | N17: ='シフト2'!O71 -> 3 | O17: ='シフト3'!P71 -> 0
A18: =SUM(D11:D17) -> 243000 | B18: ='【大井町】売上'!B18 -> 46068 | C18: ='【大井町】売上'!C18 -> 日 | D18: ='シフト3'!J77 -> 83000 | E18: ='シフト3'!K77 -> 42500 | F18: =D18-E18 -> 40500 | G18: =SUM(D18+G17) -> 537000 | H18: 60000 | I18: =H18+I17 -> 900000 | J18: =G18/I18 -> 0.59666667 | K18: =G18-I18 -> -363000 | L18: =D18/SUM(M18:O18) -> 27666.667 | M18: ='シフト2'!N76 -> 0 | N18: ='シフト2'!O76 -> 3 | O18: ='シフト3'!P76 -> 0
B19: ='【大井町】売上'!B19 -> 46069 | C19: ='【大井町】売上'!C19 -> 月 | D19: ='シフト3'!J82 -> 73000 | E19: ='シフト3'!K82 -> 42000 | F19: =D19-E19 -> 31000 | G19: =SUM(D19+G18) -> 610000 | H19: 60000 | I19: =H19+I18 -> 960000 | J19: =G19/I19 -> 0.63541667 | K19: =G19-I19 -> -350000 | L19: =D19/SUM(M19:O19) -> 24333.333 | M19: ='シフト2'!N81 -> 0 | N19: ='シフト2'!O81 -> 3 | O19: ='シフト3'!P81 -> 0
B20: ='【大井町】売上'!B20 -> 46070 | C20: ='【大井町】売上'!C20 -> 火 | D20: ='シフト3'!J87 -> 28000 | E20: ='シフト3'!K87 -> 17000 | F20: =D20-E20 -> 11000 | G20: =SUM(D20+G19) -> 638000 | H20: 60000 | I20: =H20+I19 -> 1020000 | J20: =G20/I20 -> 0.6254902 | K20: =G20-I20 -> -382000 | L20: =D20/SUM(M20:O20) -> 4666.6667 | M20: ='シフト2'!N86 -> 1 | N20: ='シフト2'!O86 -> 5 | O20: ='シフト3'!P86 -> 0
B21: ='【大井町】売上'!B21 -> 46071 | C21: ='【大井町】売上'!C21 -> 水 | D21: ='シフト3'!J92 -> 59000 | E21: ='シフト3'!K92 -> 34500 | F21: =D21-E21 -> 24500 | G21: =SUM(D21+G20) -> 697000 | H21: 60000 | I21: =H21+I20 -> 1080000 | J21: =G21/I21 -> 0.64537037 | K21: =G21-I21 -> -383000 | L21: =D21/SUM(M21:O21) -> 14750 | M21: ='シフト2'!N91 -> 0 | N21: ='シフト2'!O91 -> 3 | O21: ='シフト3'!P91 -> 1
B22: ='【大井町】売上'!B22 -> 46072 | C22: ='【大井町】売上'!C22 -> 木 | D22: ='シフト3'!J97 -> 47000 | E22: ='シフト3'!K97 -> 28500 | F22: =D22-E22 -> 18500 | G22: =SUM(D22+G21) -> 744000 | H22: 60000 | I22: =H22+I21 -> 1140000 | J22: =G22/I22 -> 0.65263158 | K22: =G22-I22 -> -396000 | L22: =D22/SUM(M22:O22) -> 9400 | M22: ='シフト2'!N96 -> 1 | N22: ='シフト2'!O96 -> 4 | O22: ='シフト3'!P96 -> 0
B23: ='【大井町】売上'!B23 -> 46073 | C23: ='【大井町】売上'!C23 -> 金 | D23: ='シフト3'!J102 -> 45000 | E23: ='シフト3'!K102 -> 27670 | F23: =D23-E23 -> 17330 | G23: =SUM(D23+G22) -> 789000 | H23: 60000 | I23: =H23+I22 -> 1200000 | J23: =G23/I23 -> 0.6575 | K23: =G23-I23 -> -411000 | L23: =D23/SUM(M23:O23) -> 15000 | M23: ='シフト2'!N101 -> 0 | N23: ='シフト2'!O101 -> 2 | O23: ='シフト3'!P101 -> 1
B24: ='【大井町】売上'!B24 -> 46074 | C24: ='【大井町】売上'!C24 -> 土 | D24: ='シフト3'!J107 -> 0 | E24: ='シフト3'!K107 -> 0 | F24: =D24-E24 -> 0 | G24: =SUM(D24+G23) -> 789000 | H24: 60000 | I24: =H24+I23 -> 1260000 | J24: =G24/I24 -> 0.62619048 | K24: =G24-I24 -> -471000 | L24: =D24/SUM(M24:O24) -> 0 | M24: ='シフト2'!N106 -> 2 | N24: ='シフト2'!O106 -> 0 | O24: ='シフト3'!P106 -> 0
A25: =SUM(D18:D24) -> 335000 | B25: ='【大井町】売上'!B25 -> 46075 | C25: ='【大井町】売上'!C25 -> 日 | D25: ='シフト3'!J112 -> 0 | E25: ='シフト3'!K112 -> 0 | F25: =D25-E25 -> 0 | G25: =SUM(D25+G24) -> 789000 | H25: 60000 | I25: =H25+I24 -> 1320000 | J25: =G25/I25 -> 0.59772727 | K25: =G25-I25 -> -531000 | L25: =D25/SUM(M25:O25) -> 0 | M25: ='シフト2'!N111 -> 3 | N25: ='シフト2'!O111 -> 2 | O25: ='シフト3'!P111 -> 0
B26: ='【大井町】売上'!B26 -> 46076 | C26: ='【大井町】売上'!C26 -> 月 | D26: ='シフト3'!J117 -> 0 | E26: ='シフト3'!K117 -> 0 | F26: =D26-E26 -> 0 | G26: =SUM(D26+G25) -> 789000 | H26: 60000 | I26: =H26+I25 -> 1380000 | J26: =G26/I26 -> 0.57173913 | K26: =G26-I26 -> -591000 | L26: =D26/SUM(M26:O26) -> #DIV/0! | M26: ='シフト2'!N116 -> 0 | N26: ='シフト2'!O116 -> 0 | O26: ='シフト3'!P116 -> 0
B27: ='【大井町】売上'!B27 -> 46077 | C27: ='【大井町】売上'!C27 -> 火 | D27: ='シフト3'!J122 -> 0 | E27: ='シフト3'!K122 -> 0 | F27: =D27-E27 -> 0 | G27: =SUM(D27+G26) -> 789000 | H27: 60000 | I27: =H27+I26 -> 1440000 | J27: =G27/I27 -> 0.54791667 | K27: =G27-I27 -> -651000 | L27: =D27/SUM(M27:O27) -> #DIV/0! | M27: ='シフト2'!N121 -> 0 | N27: ='シフト2'!O121 -> 0 | O27: ='シフト3'!P121 -> 0
B28: ='【大井町】売上'!B28 -> 46078 | C28: ='【大井町】売上'!C28 -> 水 | D28: ='シフト3'!J127 -> 0 | E28: ='シフト3'!K127 -> 0 | F28: =D28-E28 -> 0 | G28: =SUM(D28+G27) -> 789000 | H28: 60000 | I28: =H28+I27 -> 1500000 | J28: =G28/I28 -> 0.526 | K28: =G28-I28 -> -711000 | L28: =D28/SUM(M28:O28) -> #DIV/0! | M28: ='シフト2'!N126 -> 0 | N28: ='シフト2'!O126 -> 0 | O28: ='シフト3'!P126 -> 0
B29: ='【大井町】売上'!B29 -> 46079 | C29: ='【大井町】売上'!C29 -> 木 | D29: ='シフト3'!J132 -> 0 | E29: ='シフト3'!K132 -> 0 | F29: =D29-E29 -> 0 | G29: =SUM(D29+G28) -> 789000 | H29: 60000 | I29: =H29+I28 -> 1560000 | J29: =G29/I29 -> 0.50576923 | K29: =G29-I29 -> -771000 | L29: =D29/SUM(M29:O29) -> #DIV/0! | M29: ='シフト2'!N131 -> 0 | N29: ='シフト2'!O131 -> 0 | O29: ='シフト3'!P131 -> 0
B30: ='【大井町】売上'!B30 -> 46080 | C30: ='【大井町】売上'!C30 -> 金 | D30: ='シフト3'!J137 -> 0 | E30: ='シフト3'!K137 -> 0 | F30: =D30-E30 -> 0 | G30: =SUM(D30+G29) -> 789000 | H30: 60000 | I30: =H30+I29 -> 1620000 | J30: =G30/I30 -> 0.48703704 | K30: =G30-I30 -> -831000 | L30: =D30/SUM(M30:O30) -> #DIV/0! | M30: ='シフト2'!N136 -> 0 | N30: ='シフト2'!O136 -> 0 | O30: ='シフト3'!P136 -> 0
B31: ='【大井町】売上'!B31 -> 46081 | C31: ='【大井町】売上'!C31 -> 土 | D31: ='シフト3'!J142 -> 0 | E31: ='シフト3'!K142 -> 0 | F31: =D31-E31 -> 0 | G31: =SUM(D31+G30) -> 789000 | H31: 60000 | I31: =H31+I30 -> 1680000 | J31: =G31/I31 -> 0.46964286 | K31: =G31-I31 -> -891000 | L31: =D31/SUM(M31:O31) -> #DIV/0! | M31: ='シフト2'!N141 -> 0 | N31: ='シフト2'!O141 -> 0 | O31: ='シフト3'!P141 -> 0
A32: =SUM(D25:D31) -> 0 | B32: ='【大井町】売上'!B32 | C32: ='【大井町】売上'!C32 | D32: ='シフト3'!J147 -> 0 | E32: ='シフト3'!K147 -> 0 | F32: =D32-E32 -> 0 | G32: =SUM(D32+G31) -> 789000 | H32: 60000 | I32: =H32+I31 -> 1740000 | J32: =G32/I32 -> 0.45344828 | K32: =G32-I32 -> -951000 | L32: =D32/SUM(M32:O32) -> #DIV/0! | M32: ='シフト2'!N146 -> 0 | N32: ='シフト2'!O146 -> 0 | O32: ='シフト3'!P146 -> 0
A33: =SUM(D27:D33) -> 0 | B33: ='【大井町】売上'!B33 | C33: ='【大井町】売上'!C33 | D33: ='シフト3'!J152 -> 0 | E33: ='シフト3'!K152 -> 0 | F33: =D33-E33 -> 0 | G33: =SUM(D33+G32) -> 789000 | H33: 60000 | I33: =H33+I32 -> 1800000 | J33: =G33/I33 -> 0.43833333 | K33: =G33-I33 -> -1011000 | L33: =D33/SUM(M33:O33) -> #DIV/0! | M33: ='シフト2'!N151 -> 0 | N33: ='シフト2'!O151 -> 0 | O33: ='シフト3'!P151 -> 0
B34: ='【大井町】売上'!B34 | C34: ='【大井町】売上'!C34 | D34: ='シフト3'!J157 -> 0 | E34: ='シフト3'!K157 -> 0 | F34: =D34-E34 -> 0 | G34: =G33+D34 -> 789000 | H34: 60000 | I34: =H34+I33 -> 1860000 | J34: =G34/I34 -> 0.42419355 | K34: =G34-I34 -> -1071000 | L34: =D34/SUM(M34:O34) -> #DIV/0! | M34: ='シフト2'!N156 -> 0 | N34: ='シフト2'!O156 -> 0 | O34: ='シフト3'!P156 -> 0
B35: 月合計 | D35: =SUM(D4:D34) -> 789000 | E35: =SUM(E4:E34) -> 452670 | F35: =SUM(D35-E35) -> 336330 | G35: =SUM(G34) -> 789000 | H35: =SUM(H4:H34) -> 1860000 | I35: =H35 -> 1860000 | K35: 0 | L35: =AVERAGEIF(L4:L34,"<>#DIV/0!") -> 10997.052 | M35: =SUM(M4:M33) -> 18 | N35: =SUM(N4:N34) -> 62 | O35: =SUM(O4:O34) -> 5
M36: =M35/(M35+N35+O35) -> 0.21176471 | N36: =N35/(M35+N35+O35) -> 0.72941176 | O36: =O35/(M35+N35+O35) -> 0.058823529

Sheet シフト3
D1: XEBEC巣鴨203
E2: 売上 | F2: 取り分 | G2: 粗利 | J2: 売上 | K2: 取り分 | L2: 粗利
A3: 1 | B3: ='【大井町】売上'!C4 -> 日 | C3: 早番 | D3: ='管理シフト'!P6 | G3: =E3-F3 -> 0 | I3: ='管理シフト'!S6 -> てるみ | L3: =J3-K3 -> 0
D4: 新規/顧客/指名 | I4: 新規/顧客/指名
C5: 遅番 | D5: ='管理シフト'!P7 | G5: =E5-F5 -> 0 | I5: ='管理シフト'!S7 -> ののはダミー | L5: =J5-K5 -> 0 | N5: 新規 | O5: 顧客 | P5: 指名
D6: 新規/顧客/指名 | I6: 新規/顧客/指名 | N6: =E4+E6+J4+J6 -> 0 | O6: =F4+F6+K4+K6 -> 0 | P6: =G4+G6+L4+L6 -> 0
J7: =E3+E5+J3+J5 -> 0 | K7: =F3+F5+K3+K5 -> 0 | L7: =SUM(G3+G5+L3+L5+Q3+Q5) -> 0
A8: 2 | B8: ='【大井町】売上'!C5 -> 月 | C8: 早番 | D8: ='管理シフト'!P9 | G8: =E8-F8 -> 0 | I8: ='管理シフト'!S9 -> 南さなダミー | L8: =J8-K8 -> 0
D9: 新規/顧客/指名 | I9: 新規/顧客/指名
C10: 遅番 | D10: ='管理シフト'!P10 | G10: =E10-F10 -> 0 | I10: ='管理シフト'!S10 | L10: =J10-K10 -> 0 | O10: 顧客 | P10: 指名
D11: 新規/顧客/指名 | I11: 新規/顧客/指名 | N11: =E9+E11+J9+J11 -> 0 | O11: =F9+F11+K9+K11 -> 0 | P11: =G9+G11+L9+L11 -> 0
J12: =E8+E10+J8+J10 -> 0 | K12: =F8+F10+K8+K10 -> 0 | L12: =SUM(G8+G10+L8+L10+Q8+Q10) -> 0
A13: 3 | B13: ='【大井町】売上'!C6 -> 火 | C13: 早番 | D13: ='管理シフト'!P12 -> ゆかり | G13: =E13-F13 -> 0 | I13: ='管理シフト'!S12 | J13: 34000 | K13: 19000 | L13: =J13-K13 -> 15000 | S13: x
D14: 新規/顧客/指名 | I14: 新規/顧客/指名 | J14: 1 | K14: 1 | L14: 0
C15: 遅番 | D15: ='管理シフト'!P13 -> わかダミー | E15: 40000 | F15: 23500 | G15: =E15-F15 -> 16500 | I15: ='管理シフト'!S13 -> ほのか | L15: =J15-K15 -> 0 | N15: 新規 | O15: 顧客 | P15: 指名
D16: 新規/顧客/指名 | E16: 0 | F16: 1 | G16: 1 | I16: 新規/顧客/指名 | N16: =E14+E16+J14+J16 -> 1 | O16: =F14+F16+K14+K16 -> 2 | P16: =G14+G16+L14+L16 -> 1
